Process A (arrival time 482 ms) 10 CPU bursts (tau 100ms)
--> CPU burst 30 ms --> I/O burst 2820 ms
--> CPU burst 76 ms --> I/O burst 320 ms
--> CPU burst 190 ms --> I/O burst 40 ms
--> CPU burst 28 ms --> I/O burst 1100 ms
--> CPU burst 53 ms --> I/O burst 1110 ms
--> CPU burst 111 ms --> I/O burst 710 ms
--> CPU burst 91 ms --> I/O burst 1790 ms
--> CPU burst 70 ms --> I/O burst 1080 ms
--> CPU burst 63 ms --> I/O burst 520 ms
--> CPU burst 5 ms
Process B (arrival time 399 ms) 70 CPU bursts (tau 100ms)
--> CPU burst 338 ms --> I/O burst 170 ms
--> CPU burst 95 ms --> I/O burst 2560 ms
--> CPU burst 324 ms --> I/O burst 1110 ms
--> CPU burst 451 ms --> I/O burst 150 ms
--> CPU burst 57 ms --> I/O burst 1070 ms
--> CPU burst 244 ms --> I/O burst 1080 ms
--> CPU burst 84 ms --> I/O burst 170 ms
--> CPU burst 65 ms --> I/O burst 490 ms
--> CPU burst 55 ms --> I/O burst 510 ms
--> CPU burst 71 ms --> I/O burst 960 ms
--> CPU burst 20 ms --> I/O burst 850 ms
--> CPU burst 182 ms --> I/O burst 2180 ms
--> CPU burst 190 ms --> I/O burst 1450 ms
--> CPU burst 239 ms --> I/O burst 3810 ms
--> CPU burst 274 ms --> I/O burst 370 ms
--> CPU burst 19 ms --> I/O burst 980 ms
--> CPU burst 54 ms --> I/O burst 250 ms
--> CPU burst 54 ms --> I/O burst 180 ms
--> CPU burst 131 ms --> I/O burst 1870 ms
--> CPU burst 26 ms --> I/O burst 3840 ms
--> CPU burst 11 ms --> I/O burst 400 ms
--> CPU burst 150 ms --> I/O burst 80 ms
--> CPU burst 33 ms --> I/O burst 30 ms
--> CPU burst 17 ms --> I/O burst 430 ms
--> CPU burst 31 ms --> I/O burst 320 ms
--> CPU burst 102 ms --> I/O burst 10 ms
--> CPU burst 142 ms --> I/O burst 730 ms
--> CPU burst 205 ms --> I/O burst 1490 ms
--> CPU burst 72 ms --> I/O burst 400 ms
--> CPU burst 123 ms --> I/O burst 480 ms
--> CPU burst 44 ms --> I/O burst 250 ms
--> CPU burst 58 ms --> I/O burst 140 ms
--> CPU burst 121 ms --> I/O burst 2080 ms
--> CPU burst 8 ms --> I/O burst 60 ms
--> CPU burst 137 ms --> I/O burst 820 ms
--> CPU burst 145 ms --> I/O burst 3280 ms
--> CPU burst 39 ms --> I/O burst 840 ms
--> CPU burst 24 ms --> I/O burst 790 ms
--> CPU burst 119 ms --> I/O burst 1990 ms
--> CPU burst 8 ms --> I/O burst 1500 ms
--> CPU burst 136 ms --> I/O burst 510 ms
--> CPU burst 10 ms --> I/O burst 1130 ms
--> CPU burst 85 ms --> I/O burst 500 ms
--> CPU burst 318 ms --> I/O burst 1340 ms
--> CPU burst 119 ms --> I/O burst 2370 ms
--> CPU burst 43 ms --> I/O burst 620 ms
--> CPU burst 126 ms --> I/O burst 110 ms
--> CPU burst 42 ms --> I/O burst 110 ms
--> CPU burst 21 ms --> I/O burst 2540 ms
--> CPU burst 140 ms --> I/O burst 2080 ms
--> CPU burst 15 ms --> I/O burst 1290 ms
--> CPU burst 65 ms --> I/O burst 1090 ms
--> CPU burst 34 ms --> I/O burst 2120 ms
--> CPU burst 58 ms --> I/O burst 290 ms
--> CPU burst 6 ms --> I/O burst 570 ms
--> CPU burst 14 ms --> I/O burst 590 ms
--> CPU burst 156 ms --> I/O burst 250 ms
--> CPU burst 107 ms --> I/O burst 450 ms
--> CPU burst 41 ms --> I/O burst 30 ms
--> CPU burst 36 ms --> I/O burst 780 ms
--> CPU burst 228 ms --> I/O burst 170 ms
--> CPU burst 137 ms --> I/O burst 320 ms
--> CPU burst 167 ms --> I/O burst 950 ms
--> CPU burst 25 ms --> I/O burst 1180 ms
--> CPU burst 109 ms --> I/O burst 1090 ms
--> CPU burst 197 ms --> I/O burst 2270 ms
--> CPU burst 292 ms --> I/O burst 490 ms
--> CPU burst 12 ms --> I/O burst 610 ms
--> CPU burst 299 ms --> I/O burst 1450 ms
--> CPU burst 3 ms

time 0ms: Simulator started for FCFS [Q empty]
time 399ms: Process B arrived; added to ready queue [Q B]
time 401ms: Process B started using the CPU for 338ms burst [Q empty]
time 482ms: Process A arrived; added to ready queue [Q A]
time 739ms: Process B completed a CPU burst; 69 bursts to go [Q A]
time 739ms: Process B switching out of CPU; will block on I/O until time 911ms [Q A]
time 743ms: Process A started using the CPU for 30ms burst [Q empty]
time 773ms: Process A completed a CPU burst; 9 bursts to go [Q empty]
time 773ms: Process A switching out of CPU; will block on I/O until time 3595ms [Q empty]
time 911ms: Process B completed I/O; added to ready queue [Q B]
time 913ms: Process B started using the CPU for 95ms burst [Q empty]
time 1008ms: Process B completed a CPU burst; 68 bursts to go [Q empty]
time 1008ms: Process B switching out of CPU; will block on I/O until time 3570ms [Q empty]
time 3570ms: Process B completed I/O; added to ready queue [Q B]
time 3572ms: Process B started using the CPU for 324ms burst [Q empty]
time 3595ms: Process A completed I/O; added to ready queue [Q A]
time 3896ms: Process B completed a CPU burst; 67 bursts to go [Q A]
time 3896ms: Process B switching out of CPU; will block on I/O until time 5008ms [Q A]
time 3900ms: Process A started using the CPU for 76ms burst [Q empty]
time 3976ms: Process A completed a CPU burst; 8 bursts to go [Q empty]
time 3976ms: Process A switching out of CPU; will block on I/O until time 4298ms [Q empty]
time 4298ms: Process A completed I/O; added to ready queue [Q A]
time 4300ms: Process A started using the CPU for 190ms burst [Q empty]
time 4490ms: Process A completed a CPU burst; 7 bursts to go [Q empty]
time 4490ms: Process A switching out of CPU; will block on I/O until time 4532ms [Q empty]
time 4532ms: Process A completed I/O; added to ready queue [Q A]
time 4534ms: Process A started using the CPU for 28ms burst [Q empty]
time 4562ms: Process A completed a CPU burst; 6 bursts to go [Q empty]
time 4562ms: Process A switching out of CPU; will block on I/O until time 5664ms [Q empty]
time 5008ms: Process B completed I/O; added to ready queue [Q B]
time 5010ms: Process B started using the CPU for 451ms burst [Q empty]
time 5461ms: Process B completed a CPU burst; 66 bursts to go [Q empty]
time 5461ms: Process B switching out of CPU; will block on I/O until time 5613ms [Q empty]
time 5613ms: Process B completed I/O; added to ready queue [Q B]
time 5615ms: Process B started using the CPU for 57ms burst [Q empty]
time 5664ms: Process A completed I/O; added to ready queue [Q A]
time 5672ms: Process B completed a CPU burst; 65 bursts to go [Q A]
time 5672ms: Process B switching out of CPU; will block on I/O until time 6744ms [Q A]
time 5676ms: Process A started using the CPU for 53ms burst [Q empty]
time 5729ms: Process A completed a CPU burst; 5 bursts to go [Q empty]
time 5729ms: Process A switching out of CPU; will block on I/O until time 6841ms [Q empty]
time 6744ms: Process B completed I/O; added to ready queue [Q B]
time 6746ms: Process B started using the CPU for 244ms burst [Q empty]
time 6841ms: Process A completed I/O; added to ready queue [Q A]
time 6990ms: Process B completed a CPU burst; 64 bursts to go [Q A]
time 6990ms: Process B switching out of CPU; will block on I/O until time 8072ms [Q A]
time 6994ms: Process A started using the CPU for 111ms burst [Q empty]
time 7105ms: Process A completed a CPU burst; 4 bursts to go [Q empty]
time 7105ms: Process A switching out of CPU; will block on I/O until time 7817ms [Q empty]
time 7817ms: Process A completed I/O; added to ready queue [Q A]
time 7819ms: Process A started using the CPU for 91ms burst [Q empty]
time 7910ms: Process A completed a CPU burst; 3 bursts to go [Q empty]
time 7910ms: Process A switching out of CPU; will block on I/O until time 9702ms [Q empty]
time 8072ms: Process B completed I/O; added to ready queue [Q B]
time 8074ms: Process B started using the CPU for 84ms burst [Q empty]
time 8158ms: Process B completed a CPU burst; 63 bursts to go [Q empty]
time 8158ms: Process B switching out of CPU; will block on I/O until time 8330ms [Q empty]
time 8330ms: Process B completed I/O; added to ready queue [Q B]
time 8332ms: Process B started using the CPU for 65ms burst [Q empty]
time 8397ms: Process B completed a CPU burst; 62 bursts to go [Q empty]
time 8397ms: Process B switching out of CPU; will block on I/O until time 8889ms [Q empty]
time 8889ms: Process B completed I/O; added to ready queue [Q B]
time 8891ms: Process B started using the CPU for 55ms burst [Q empty]
time 8946ms: Process B completed a CPU burst; 61 bursts to go [Q empty]
time 8946ms: Process B switching out of CPU; will block on I/O until time 9458ms [Q empty]
time 9458ms: Process B completed I/O; added to ready queue [Q B]
time 9460ms: Process B started using the CPU for 71ms burst [Q empty]
time 9531ms: Process B completed a CPU burst; 60 bursts to go [Q empty]
time 9531ms: Process B switching out of CPU; will block on I/O until time 10493ms [Q empty]
time 9702ms: Process A completed I/O; added to ready queue [Q A]
time 9704ms: Process A started using the CPU for 70ms burst [Q empty]
time 9774ms: Process A completed a CPU burst; 2 bursts to go [Q empty]
time 9774ms: Process A switching out of CPU; will block on I/O until time 10856ms [Q empty]
time 10493ms: Process B completed I/O; added to ready queue [Q B]
time 10495ms: Process B started using the CPU for 20ms burst [Q empty]
time 10515ms: Process B completed a CPU burst; 59 bursts to go [Q empty]
time 10515ms: Process B switching out of CPU; will block on I/O until time 11367ms [Q empty]
time 10856ms: Process A completed I/O; added to ready queue [Q A]
time 10858ms: Process A started using the CPU for 63ms burst [Q empty]
time 10921ms: Process A completed a CPU burst; 1 burst to go [Q empty]
time 10921ms: Process A switching out of CPU; will block on I/O until time 11443ms [Q empty]
time 11367ms: Process B completed I/O; added to ready queue [Q B]
time 11369ms: Process B started using the CPU for 182ms burst [Q empty]
time 11443ms: Process A completed I/O; added to ready queue [Q A]
time 11551ms: Process B completed a CPU burst; 58 bursts to go [Q A]
time 11551ms: Process B switching out of CPU; will block on I/O until time 13733ms [Q A]
time 11555ms: Process A started using the CPU for 5ms burst [Q empty]
time 11560ms: Process A terminated [Q empty]
time 13733ms: Process B completed I/O; added to ready queue [Q B]
time 13735ms: Process B started using the CPU for 190ms burst [Q empty]
time 13925ms: Process B completed a CPU burst; 57 bursts to go [Q empty]
time 13925ms: Process B switching out of CPU; will block on I/O until time 15377ms [Q empty]
time 15377ms: Process B completed I/O; added to ready queue [Q B]
time 15379ms: Process B started using the CPU for 239ms burst [Q empty]
time 15618ms: Process B completed a CPU burst; 56 bursts to go [Q empty]
time 15618ms: Process B switching out of CPU; will block on I/O until time 19430ms [Q empty]
time 19430ms: Process B completed I/O; added to ready queue [Q B]
time 19432ms: Process B started using the CPU for 274ms burst [Q empty]
time 19706ms: Process B completed a CPU burst; 55 bursts to go [Q empty]
time 19706ms: Process B switching out of CPU; will block on I/O until time 20078ms [Q empty]
time 20078ms: Process B completed I/O; added to ready queue [Q B]
time 20080ms: Process B started using the CPU for 19ms burst [Q empty]
time 20099ms: Process B completed a CPU burst; 54 bursts to go [Q empty]
time 20099ms: Process B switching out of CPU; will block on I/O until time 21081ms [Q empty]
time 21081ms: Process B completed I/O; added to ready queue [Q B]
time 21083ms: Process B started using the CPU for 54ms burst [Q empty]
time 21137ms: Process B completed a CPU burst; 53 bursts to go [Q empty]
time 21137ms: Process B switching out of CPU; will block on I/O until time 21389ms [Q empty]
time 21389ms: Process B completed I/O; added to ready queue [Q B]
time 21391ms: Process B started using the CPU for 54ms burst [Q empty]
time 21445ms: Process B completed a CPU burst; 52 bursts to go [Q empty]
time 21445ms: Process B switching out of CPU; will block on I/O until time 21627ms [Q empty]
time 21627ms: Process B completed I/O; added to ready queue [Q B]
time 21629ms: Process B started using the CPU for 131ms burst [Q empty]
time 21760ms: Process B completed a CPU burst; 51 bursts to go [Q empty]
time 21760ms: Process B switching out of CPU; will block on I/O until time 23632ms [Q empty]
time 23632ms: Process B completed I/O; added to ready queue [Q B]
time 23634ms: Process B started using the CPU for 26ms burst [Q empty]
time 23660ms: Process B completed a CPU burst; 50 bursts to go [Q empty]
time 23660ms: Process B switching out of CPU; will block on I/O until time 27502ms [Q empty]
time 27502ms: Process B completed I/O; added to ready queue [Q B]
time 27504ms: Process B started using the CPU for 11ms burst [Q empty]
time 27515ms: Process B completed a CPU burst; 49 bursts to go [Q empty]
time 27515ms: Process B switching out of CPU; will block on I/O until time 27917ms [Q empty]
time 27917ms: Process B completed I/O; added to ready queue [Q B]
time 27919ms: Process B started using the CPU for 150ms burst [Q empty]
time 28069ms: Process B completed a CPU burst; 48 bursts to go [Q empty]
time 28069ms: Process B switching out of CPU; will block on I/O until time 28151ms [Q empty]
time 28151ms: Process B completed I/O; added to ready queue [Q B]
time 28153ms: Process B started using the CPU for 33ms burst [Q empty]
time 28186ms: Process B completed a CPU burst; 47 bursts to go [Q empty]
time 28186ms: Process B switching out of CPU; will block on I/O until time 28218ms [Q empty]
time 28218ms: Process B completed I/O; added to ready queue [Q B]
time 28220ms: Process B started using the CPU for 17ms burst [Q empty]
time 28237ms: Process B completed a CPU burst; 46 bursts to go [Q empty]
time 28237ms: Process B switching out of CPU; will block on I/O until time 28669ms [Q empty]
time 28669ms: Process B completed I/O; added to ready queue [Q B]
time 28671ms: Process B started using the CPU for 31ms burst [Q empty]
time 28702ms: Process B completed a CPU burst; 45 bursts to go [Q empty]
time 28702ms: Process B switching out of CPU; will block on I/O until time 29024ms [Q empty]
time 29024ms: Process B completed I/O; added to ready queue [Q B]
time 29026ms: Process B started using the CPU for 102ms burst [Q empty]
time 29128ms: Process B completed a CPU burst; 44 bursts to go [Q empty]
time 29128ms: Process B switching out of CPU; will block on I/O until time 29140ms [Q empty]
time 29140ms: Process B completed I/O; added to ready queue [Q B]
time 29142ms: Process B started using the CPU for 142ms burst [Q empty]
time 29284ms: Process B completed a CPU burst; 43 bursts to go [Q empty]
time 29284ms: Process B switching out of CPU; will block on I/O until time 30016ms [Q empty]
time 30016ms: Process B completed I/O; added to ready queue [Q B]
time 30018ms: Process B started using the CPU for 205ms burst [Q empty]
time 30223ms: Process B completed a CPU burst; 42 bursts to go [Q empty]
time 30223ms: Process B switching out of CPU; will block on I/O until time 31715ms [Q empty]
time 31715ms: Process B completed I/O; added to ready queue [Q B]
time 31717ms: Process B started using the CPU for 72ms burst [Q empty]
time 31789ms: Process B completed a CPU burst; 41 bursts to go [Q empty]
time 31789ms: Process B switching out of CPU; will block on I/O until time 32191ms [Q empty]
time 32191ms: Process B completed I/O; added to ready queue [Q B]
time 32193ms: Process B started using the CPU for 123ms burst [Q empty]
time 32316ms: Process B completed a CPU burst; 40 bursts to go [Q empty]
time 32316ms: Process B switching out of CPU; will block on I/O until time 32798ms [Q empty]
time 32798ms: Process B completed I/O; added to ready queue [Q B]
time 32800ms: Process B started using the CPU for 44ms burst [Q empty]
time 32844ms: Process B completed a CPU burst; 39 bursts to go [Q empty]
time 32844ms: Process B switching out of CPU; will block on I/O until time 33096ms [Q empty]
time 33096ms: Process B completed I/O; added to ready queue [Q B]
time 33098ms: Process B started using the CPU for 58ms burst [Q empty]
time 33156ms: Process B completed a CPU burst; 38 bursts to go [Q empty]
time 33156ms: Process B switching out of CPU; will block on I/O until time 33298ms [Q empty]
time 33298ms: Process B completed I/O; added to ready queue [Q B]
time 33300ms: Process B started using the CPU for 121ms burst [Q empty]
time 33421ms: Process B completed a CPU burst; 37 bursts to go [Q empty]
time 33421ms: Process B switching out of CPU; will block on I/O until time 35503ms [Q empty]
time 35503ms: Process B completed I/O; added to ready queue [Q B]
time 35505ms: Process B started using the CPU for 8ms burst [Q empty]
time 35513ms: Process B completed a CPU burst; 36 bursts to go [Q empty]
time 35513ms: Process B switching out of CPU; will block on I/O until time 35575ms [Q empty]
time 35575ms: Process B completed I/O; added to ready queue [Q B]
time 35577ms: Process B started using the CPU for 137ms burst [Q empty]
time 35714ms: Process B completed a CPU burst; 35 bursts to go [Q empty]
time 35714ms: Process B switching out of CPU; will block on I/O until time 36536ms [Q empty]
time 36536ms: Process B completed I/O; added to ready queue [Q B]
time 36538ms: Process B started using the CPU for 145ms burst [Q empty]
time 36683ms: Process B completed a CPU burst; 34 bursts to go [Q empty]
time 36683ms: Process B switching out of CPU; will block on I/O until time 39965ms [Q empty]
time 39965ms: Process B completed I/O; added to ready queue [Q B]
time 39967ms: Process B started using the CPU for 39ms burst [Q empty]
time 40006ms: Process B completed a CPU burst; 33 bursts to go [Q empty]
time 40006ms: Process B switching out of CPU; will block on I/O until time 40848ms [Q empty]
time 40848ms: Process B completed I/O; added to ready queue [Q B]
time 40850ms: Process B started using the CPU for 24ms burst [Q empty]
time 40874ms: Process B completed a CPU burst; 32 bursts to go [Q empty]
time 40874ms: Process B switching out of CPU; will block on I/O until time 41666ms [Q empty]
time 41666ms: Process B completed I/O; added to ready queue [Q B]
time 41668ms: Process B started using the CPU for 119ms burst [Q empty]
time 41787ms: Process B completed a CPU burst; 31 bursts to go [Q empty]
time 41787ms: Process B switching out of CPU; will block on I/O until time 43779ms [Q empty]
time 43779ms: Process B completed I/O; added to ready queue [Q B]
time 43781ms: Process B started using the CPU for 8ms burst [Q empty]
time 43789ms: Process B completed a CPU burst; 30 bursts to go [Q empty]
time 43789ms: Process B switching out of CPU; will block on I/O until time 45291ms [Q empty]
time 45291ms: Process B completed I/O; added to ready queue [Q B]
time 45293ms: Process B started using the CPU for 136ms burst [Q empty]
time 45429ms: Process B completed a CPU burst; 29 bursts to go [Q empty]
time 45429ms: Process B switching out of CPU; will block on I/O until time 45941ms [Q empty]
time 45941ms: Process B completed I/O; added to ready queue [Q B]
time 45943ms: Process B started using the CPU for 10ms burst [Q empty]
time 45953ms: Process B completed a CPU burst; 28 bursts to go [Q empty]
time 45953ms: Process B switching out of CPU; will block on I/O until time 47085ms [Q empty]
time 47085ms: Process B completed I/O; added to ready queue [Q B]
time 47087ms: Process B started using the CPU for 85ms burst [Q empty]
time 47172ms: Process B completed a CPU burst; 27 bursts to go [Q empty]
time 47172ms: Process B switching out of CPU; will block on I/O until time 47674ms [Q empty]
time 47674ms: Process B completed I/O; added to ready queue [Q B]
time 47676ms: Process B started using the CPU for 318ms burst [Q empty]
time 47994ms: Process B completed a CPU burst; 26 bursts to go [Q empty]
time 47994ms: Process B switching out of CPU; will block on I/O until time 49336ms [Q empty]
time 49336ms: Process B completed I/O; added to ready queue [Q B]
time 49338ms: Process B started using the CPU for 119ms burst [Q empty]
time 49457ms: Process B completed a CPU burst; 25 bursts to go [Q empty]
time 49457ms: Process B switching out of CPU; will block on I/O until time 51829ms [Q empty]
time 51829ms: Process B completed I/O; added to ready queue [Q B]
time 51831ms: Process B started using the CPU for 43ms burst [Q empty]
time 51874ms: Process B completed a CPU burst; 24 bursts to go [Q empty]
time 51874ms: Process B switching out of CPU; will block on I/O until time 52496ms [Q empty]
time 52496ms: Process B completed I/O; added to ready queue [Q B]
time 52498ms: Process B started using the CPU for 126ms burst [Q empty]
time 52624ms: Process B completed a CPU burst; 23 bursts to go [Q empty]
time 52624ms: Process B switching out of CPU; will block on I/O until time 52736ms [Q empty]
time 52736ms: Process B completed I/O; added to ready queue [Q B]
time 52738ms: Process B started using the CPU for 42ms burst [Q empty]
time 52780ms: Process B completed a CPU burst; 22 bursts to go [Q empty]
time 52780ms: Process B switching out of CPU; will block on I/O until time 52892ms [Q empty]
time 52892ms: Process B completed I/O; added to ready queue [Q B]
time 52894ms: Process B started using the CPU for 21ms burst [Q empty]
time 52915ms: Process B completed a CPU burst; 21 bursts to go [Q empty]
time 52915ms: Process B switching out of CPU; will block on I/O until time 55457ms [Q empty]
time 55457ms: Process B completed I/O; added to ready queue [Q B]
time 55459ms: Process B started using the CPU for 140ms burst [Q empty]
time 55599ms: Process B completed a CPU burst; 20 bursts to go [Q empty]
time 55599ms: Process B switching out of CPU; will block on I/O until time 57681ms [Q empty]
time 57681ms: Process B completed I/O; added to ready queue [Q B]
time 57683ms: Process B started using the CPU for 15ms burst [Q empty]
time 57698ms: Process B completed a CPU burst; 19 bursts to go [Q empty]
time 57698ms: Process B switching out of CPU; will block on I/O until time 58990ms [Q empty]
time 58990ms: Process B completed I/O; added to ready queue [Q B]
time 58992ms: Process B started using the CPU for 65ms burst [Q empty]
time 59057ms: Process B completed a CPU burst; 18 bursts to go [Q empty]
time 59057ms: Process B switching out of CPU; will block on I/O until time 60149ms [Q empty]
time 60149ms: Process B completed I/O; added to ready queue [Q B]
time 60151ms: Process B started using the CPU for 34ms burst [Q empty]
time 60185ms: Process B completed a CPU burst; 17 bursts to go [Q empty]
time 60185ms: Process B switching out of CPU; will block on I/O until time 62307ms [Q empty]
time 62307ms: Process B completed I/O; added to ready queue [Q B]
time 62309ms: Process B started using the CPU for 58ms burst [Q empty]
time 62367ms: Process B completed a CPU burst; 16 bursts to go [Q empty]
time 62367ms: Process B switching out of CPU; will block on I/O until time 62659ms [Q empty]
time 62659ms: Process B completed I/O; added to ready queue [Q B]
time 62661ms: Process B started using the CPU for 6ms burst [Q empty]
time 62667ms: Process B completed a CPU burst; 15 bursts to go [Q empty]
time 62667ms: Process B switching out of CPU; will block on I/O until time 63239ms [Q empty]
time 63239ms: Process B completed I/O; added to ready queue [Q B]
time 63241ms: Process B started using the CPU for 14ms burst [Q empty]
time 63255ms: Process B completed a CPU burst; 14 bursts to go [Q empty]
time 63255ms: Process B switching out of CPU; will block on I/O until time 63847ms [Q empty]
time 63847ms: Process B completed I/O; added to ready queue [Q B]
time 63849ms: Process B started using the CPU for 156ms burst [Q empty]
time 64005ms: Process B completed a CPU burst; 13 bursts to go [Q empty]
time 64005ms: Process B switching out of CPU; will block on I/O until time 64257ms [Q empty]
time 64257ms: Process B completed I/O; added to ready queue [Q B]
time 64259ms: Process B started using the CPU for 107ms burst [Q empty]
time 64366ms: Process B completed a CPU burst; 12 bursts to go [Q empty]
time 64366ms: Process B switching out of CPU; will block on I/O until time 64818ms [Q empty]
time 64818ms: Process B completed I/O; added to ready queue [Q B]
time 64820ms: Process B started using the CPU for 41ms burst [Q empty]
time 64861ms: Process B completed a CPU burst; 11 bursts to go [Q empty]
time 64861ms: Process B switching out of CPU; will block on I/O until time 64893ms [Q empty]
time 64893ms: Process B completed I/O; added to ready queue [Q B]
time 64895ms: Process B started using the CPU for 36ms burst [Q empty]
time 64931ms: Process B completed a CPU burst; 10 bursts to go [Q empty]
time 64931ms: Process B switching out of CPU; will block on I/O until time 65713ms [Q empty]
time 65713ms: Process B completed I/O; added to ready queue [Q B]
time 65715ms: Process B started using the CPU for 228ms burst [Q empty]
time 65943ms: Process B completed a CPU burst; 9 bursts to go [Q empty]
time 65943ms: Process B switching out of CPU; will block on I/O until time 66115ms [Q empty]
time 66115ms: Process B completed I/O; added to ready queue [Q B]
time 66117ms: Process B started using the CPU for 137ms burst [Q empty]
time 66254ms: Process B completed a CPU burst; 8 bursts to go [Q empty]
time 66254ms: Process B switching out of CPU; will block on I/O until time 66576ms [Q empty]
time 66576ms: Process B completed I/O; added to ready queue [Q B]
time 66578ms: Process B started using the CPU for 167ms burst [Q empty]
time 66745ms: Process B completed a CPU burst; 7 bursts to go [Q empty]
time 66745ms: Process B switching out of CPU; will block on I/O until time 67697ms [Q empty]
time 67697ms: Process B completed I/O; added to ready queue [Q B]
time 67699ms: Process B started using the CPU for 25ms burst [Q empty]
time 67724ms: Process B completed a CPU burst; 6 bursts to go [Q empty]
time 67724ms: Process B switching out of CPU; will block on I/O until time 68906ms [Q empty]
time 68906ms: Process B completed I/O; added to ready queue [Q B]
time 68908ms: Process B started using the CPU for 109ms burst [Q empty]
time 69017ms: Process B completed a CPU burst; 5 bursts to go [Q empty]
time 69017ms: Process B switching out of CPU; will block on I/O until time 70109ms [Q empty]
time 70109ms: Process B completed I/O; added to ready queue [Q B]
time 70111ms: Process B started using the CPU for 197ms burst [Q empty]
time 70308ms: Process B completed a CPU burst; 4 bursts to go [Q empty]
time 70308ms: Process B switching out of CPU; will block on I/O until time 72580ms [Q empty]
time 72580ms: Process B completed I/O; added to ready queue [Q B]
time 72582ms: Process B started using the CPU for 292ms burst [Q empty]
time 72874ms: Process B completed a CPU burst; 3 bursts to go [Q empty]
time 72874ms: Process B switching out of CPU; will block on I/O until time 73366ms [Q empty]
time 73366ms: Process B completed I/O; added to ready queue [Q B]
time 73368ms: Process B started using the CPU for 12ms burst [Q empty]
time 73380ms: Process B completed a CPU burst; 2 bursts to go [Q empty]
time 73380ms: Process B switching out of CPU; will block on I/O until time 73992ms [Q empty]
time 73992ms: Process B completed I/O; added to ready queue [Q B]
time 73994ms: Process B started using the CPU for 299ms burst [Q empty]
time 74293ms: Process B completed a CPU burst; 1 burst to go [Q empty]
time 74293ms: Process B switching out of CPU; will block on I/O until time 75745ms [Q empty]
time 75745ms: Process B completed I/O; added to ready queue [Q B]
time 75747ms: Process B started using the CPU for 3ms burst [Q empty]
time 75750ms: Process B terminated [Q empty]
time 75752ms: Simulator ended for FCFS [Q empty]

time 0ms: Simulator started for SJF [Q empty]
time 399ms: Process B (tau 100ms) arrived; added to ready queue [Q B]
time 401ms: Process B (tau 100ms) started using the CPU for 338ms burst [Q empty]
time 482ms: Process A (tau 100ms) arrived; added to ready queue [Q A]
time 739ms: Process B (tau 100ms) completed a CPU burst; 69 bursts to go [Q A]
time 739ms: Recalculated tau from 100ms to 219ms for process B [Q A]
time 739ms: Process B switching out of CPU; will block on I/O until time 911ms [Q A]
time 743ms: Process A (tau 100ms) started using the CPU for 30ms burst [Q empty]
time 773ms: Process A (tau 100ms) completed a CPU burst; 9 bursts to go [Q empty]
time 773ms: Recalculated tau from 100ms to 65ms for process A [Q empty]
time 773ms: Process A switching out of CPU; will block on I/O until time 3595ms [Q empty]
time 911ms: Process B (tau 219ms) completed I/O; added to ready queue [Q B]
time 913ms: Process B (tau 219ms) started using the CPU for 95ms burst [Q empty]
time 1008ms: Process B (tau 219ms) completed a CPU burst; 68 bursts to go [Q empty]
time 1008ms: Recalculated tau from 219ms to 158ms for process B [Q empty]
time 1008ms: Process B switching out of CPU; will block on I/O until time 3570ms [Q empty]
time 3570ms: Process B (tau 158ms) completed I/O; added to ready queue [Q B]
time 3572ms: Process B (tau 158ms) started using the CPU for 324ms burst [Q empty]
time 3595ms: Process A (tau 65ms) completed I/O; added to ready queue [Q A]
time 3896ms: Process B (tau 158ms) completed a CPU burst; 67 bursts to go [Q A]
time 3896ms: Recalculated tau from 158ms to 241ms for process B [Q A]
time 3896ms: Process B switching out of CPU; will block on I/O until time 5008ms [Q A]
time 3900ms: Process A (tau 65ms) started using the CPU for 76ms burst [Q empty]
time 3976ms: Process A (tau 65ms) completed a CPU burst; 8 bursts to go [Q empty]
time 3976ms: Recalculated tau from 65ms to 71ms for process A [Q empty]
time 3976ms: Process A switching out of CPU; will block on I/O until time 4298ms [Q empty]
time 4298ms: Process A (tau 71ms) completed I/O; added to ready queue [Q A]
time 4300ms: Process A (tau 71ms) started using the CPU for 190ms burst [Q empty]
time 4490ms: Process A (tau 71ms) completed a CPU burst; 7 bursts to go [Q empty]
time 4490ms: Recalculated tau from 71ms to 131ms for process A [Q empty]
time 4490ms: Process A switching out of CPU; will block on I/O until time 4532ms [Q empty]
time 4532ms: Process A (tau 131ms) completed I/O; added to ready queue [Q A]
time 4534ms: Process A (tau 131ms) started using the CPU for 28ms burst [Q empty]
time 4562ms: Process A (tau 131ms) completed a CPU burst; 6 bursts to go [Q empty]
time 4562ms: Recalculated tau from 131ms to 80ms for process A [Q empty]
time 4562ms: Process A switching out of CPU; will block on I/O until time 5664ms [Q empty]
time 5008ms: Process B (tau 241ms) completed I/O; added to ready queue [Q B]
time 5010ms: Process B (tau 241ms) started using the CPU for 451ms burst [Q empty]
time 5461ms: Process B (tau 241ms) completed a CPU burst; 66 bursts to go [Q empty]
time 5461ms: Recalculated tau from 241ms to 347ms for process B [Q empty]
time 5461ms: Process B switching out of CPU; will block on I/O until time 5613ms [Q empty]
time 5613ms: Process B (tau 347ms) completed I/O; added to ready queue [Q B]
time 5615ms: Process B (tau 347ms) started using the CPU for 57ms burst [Q empty]
time 5664ms: Process A (tau 80ms) completed I/O; added to ready queue [Q A]
time 5672ms: Process B (tau 347ms) completed a CPU burst; 65 bursts to go [Q A]
time 5672ms: Recalculated tau from 347ms to 203ms for process B [Q A]
time 5672ms: Process B switching out of CPU; will block on I/O until time 6744ms [Q A]
time 5676ms: Process A (tau 80ms) started using the CPU for 53ms burst [Q empty]
time 5729ms: Process A (tau 80ms) completed a CPU burst; 5 bursts to go [Q empty]
time 5729ms: Recalculated tau from 80ms to 67ms for process A [Q empty]
time 5729ms: Process A switching out of CPU; will block on I/O until time 6841ms [Q empty]
time 6744ms: Process B (tau 203ms) completed I/O; added to ready queue [Q B]
time 6746ms: Process B (tau 203ms) started using the CPU for 244ms burst [Q empty]
time 6841ms: Process A (tau 67ms) completed I/O; added to ready queue [Q A]
time 6990ms: Process B (tau 203ms) completed a CPU burst; 64 bursts to go [Q A]
time 6990ms: Recalculated tau from 203ms to 224ms for process B [Q A]
time 6990ms: Process B switching out of CPU; will block on I/O until time 8072ms [Q A]
time 6994ms: Process A (tau 67ms) started using the CPU for 111ms burst [Q empty]
time 7105ms: Process A (tau 67ms) completed a CPU burst; 4 bursts to go [Q empty]
time 7105ms: Recalculated tau from 67ms to 90ms for process A [Q empty]
time 7105ms: Process A switching out of CPU; will block on I/O until time 7817ms [Q empty]
time 7817ms: Process A (tau 90ms) completed I/O; added to ready queue [Q A]
time 7819ms: Process A (tau 90ms) started using the CPU for 91ms burst [Q empty]
time 7910ms: Process A (tau 90ms) completed a CPU burst; 3 bursts to go [Q empty]
time 7910ms: Recalculated tau from 90ms to 91ms for process A [Q empty]
time 7910ms: Process A switching out of CPU; will block on I/O until time 9702ms [Q empty]
time 8072ms: Process B (tau 224ms) completed I/O; added to ready queue [Q B]
time 8074ms: Process B (tau 224ms) started using the CPU for 84ms burst [Q empty]
time 8158ms: Process B (tau 224ms) completed a CPU burst; 63 bursts to go [Q empty]
time 8158ms: Recalculated tau from 224ms to 154ms for process B [Q empty]
time 8158ms: Process B switching out of CPU; will block on I/O until time 8330ms [Q empty]
time 8330ms: Process B (tau 154ms) completed I/O; added to ready queue [Q B]
time 8332ms: Process B (tau 154ms) started using the CPU for 65ms burst [Q empty]
time 8397ms: Process B (tau 154ms) completed a CPU burst; 62 bursts to go [Q empty]
time 8397ms: Recalculated tau from 154ms to 110ms for process B [Q empty]
time 8397ms: Process B switching out of CPU; will block on I/O until time 8889ms [Q empty]
time 8889ms: Process B (tau 110ms) completed I/O; added to ready queue [Q B]
time 8891ms: Process B (tau 110ms) started using the CPU for 55ms burst [Q empty]
time 8946ms: Process B (tau 110ms) completed a CPU burst; 61 bursts to go [Q empty]
time 8946ms: Recalculated tau from 110ms to 83ms for process B [Q empty]
time 8946ms: Process B switching out of CPU; will block on I/O until time 9458ms [Q empty]
time 9458ms: Process B (tau 83ms) completed I/O; added to ready queue [Q B]
time 9460ms: Process B (tau 83ms) started using the CPU for 71ms burst [Q empty]
time 9531ms: Process B (tau 83ms) completed a CPU burst; 60 bursts to go [Q empty]
time 9531ms: Recalculated tau from 83ms to 78ms for process B [Q empty]
time 9531ms: Process B switching out of CPU; will block on I/O until time 10493ms [Q empty]
time 9702ms: Process A (tau 91ms) completed I/O; added to ready queue [Q A]
time 9704ms: Process A (tau 91ms) started using the CPU for 70ms burst [Q empty]
time 9774ms: Process A (tau 91ms) completed a CPU burst; 2 bursts to go [Q empty]
time 9774ms: Recalculated tau from 91ms to 81ms for process A [Q empty]
time 9774ms: Process A switching out of CPU; will block on I/O until time 10856ms [Q empty]
time 10493ms: Process B (tau 78ms) completed I/O; added to ready queue [Q B]
time 10495ms: Process B (tau 78ms) started using the CPU for 20ms burst [Q empty]
time 10515ms: Process B (tau 78ms) completed a CPU burst; 59 bursts to go [Q empty]
time 10515ms: Recalculated tau from 78ms to 49ms for process B [Q empty]
time 10515ms: Process B switching out of CPU; will block on I/O until time 11367ms [Q empty]
time 10856ms: Process A (tau 81ms) completed I/O; added to ready queue [Q A]
time 10858ms: Process A (tau 81ms) started using the CPU for 63ms burst [Q empty]
time 10921ms: Process A (tau 81ms) completed a CPU burst; 1 burst to go [Q empty]
time 10921ms: Recalculated tau from 81ms to 73ms for process A [Q empty]
time 10921ms: Process A switching out of CPU; will block on I/O until time 11443ms [Q empty]
time 11367ms: Process B (tau 49ms) completed I/O; added to ready queue [Q B]
time 11369ms: Process B (tau 49ms) started using the CPU for 182ms burst [Q empty]
time 11443ms: Process A (tau 73ms) completed I/O; added to ready queue [Q A]
time 11551ms: Process B (tau 49ms) completed a CPU burst; 58 bursts to go [Q A]
time 11551ms: Recalculated tau from 49ms to 116ms for process B [Q A]
time 11551ms: Process B switching out of CPU; will block on I/O until time 13733ms [Q A]
time 11555ms: Process A (tau 73ms) started using the CPU for 5ms burst [Q empty]
time 11560ms: Process A terminated [Q empty]
time 13733ms: Process B (tau 116ms) completed I/O; added to ready queue [Q B]
time 13735ms: Process B (tau 116ms) started using the CPU for 190ms burst [Q empty]
time 13925ms: Process B (tau 116ms) completed a CPU burst; 57 bursts to go [Q empty]
time 13925ms: Recalculated tau from 116ms to 153ms for process B [Q empty]
time 13925ms: Process B switching out of CPU; will block on I/O until time 15377ms [Q empty]
time 15377ms: Process B (tau 153ms) completed I/O; added to ready queue [Q B]
time 15379ms: Process B (tau 153ms) started using the CPU for 239ms burst [Q empty]
time 15618ms: Process B (tau 153ms) completed a CPU burst; 56 bursts to go [Q empty]
time 15618ms: Recalculated tau from 153ms to 197ms for process B [Q empty]
time 15618ms: Process B switching out of CPU; will block on I/O until time 19430ms [Q empty]
time 19430ms: Process B (tau 197ms) completed I/O; added to ready queue [Q B]
time 19432ms: Process B (tau 197ms) started using the CPU for 274ms burst [Q empty]
time 19706ms: Process B (tau 197ms) completed a CPU burst; 55 bursts to go [Q empty]
time 19706ms: Recalculated tau from 197ms to 236ms for process B [Q empty]
time 19706ms: Process B switching out of CPU; will block on I/O until time 20078ms [Q empty]
time 20078ms: Process B (tau 236ms) completed I/O; added to ready queue [Q B]
time 20080ms: Process B (tau 236ms) started using the CPU for 19ms burst [Q empty]
time 20099ms: Process B (tau 236ms) completed a CPU burst; 54 bursts to go [Q empty]
time 20099ms: Recalculated tau from 236ms to 128ms for process B [Q empty]
time 20099ms: Process B switching out of CPU; will block on I/O until time 21081ms [Q empty]
time 21081ms: Process B (tau 128ms) completed I/O; added to ready queue [Q B]
time 21083ms: Process B (tau 128ms) started using the CPU for 54ms burst [Q empty]
time 21137ms: Process B (tau 128ms) completed a CPU burst; 53 bursts to go [Q empty]
time 21137ms: Recalculated tau from 128ms to 91ms for process B [Q empty]
time 21137ms: Process B switching out of CPU; will block on I/O until time 21389ms [Q empty]
time 21389ms: Process B (tau 91ms) completed I/O; added to ready queue [Q B]
time 21391ms: Process B (tau 91ms) started using the CPU for 54ms burst [Q empty]
time 21445ms: Process B (tau 91ms) completed a CPU burst; 52 bursts to go [Q empty]
time 21445ms: Recalculated tau from 91ms to 73ms for process B [Q empty]
time 21445ms: Process B switching out of CPU; will block on I/O until time 21627ms [Q empty]
time 21627ms: Process B (tau 73ms) completed I/O; added to ready queue [Q B]
time 21629ms: Process B (tau 73ms) started using the CPU for 131ms burst [Q empty]
time 21760ms: Process B (tau 73ms) completed a CPU burst; 51 bursts to go [Q empty]
time 21760ms: Recalculated tau from 73ms to 103ms for process B [Q empty]
time 21760ms: Process B switching out of CPU; will block on I/O until time 23632ms [Q empty]
time 23632ms: Process B (tau 103ms) completed I/O; added to ready queue [Q B]
time 23634ms: Process B (tau 103ms) started using the CPU for 26ms burst [Q empty]
time 23660ms: Process B (tau 103ms) completed a CPU burst; 50 bursts to go [Q empty]
time 23660ms: Recalculated tau from 103ms to 65ms for process B [Q empty]
time 23660ms: Process B switching out of CPU; will block on I/O until time 27502ms [Q empty]
time 27502ms: Process B (tau 65ms) completed I/O; added to ready queue [Q B]
time 27504ms: Process B (tau 65ms) started using the CPU for 11ms burst [Q empty]
time 27515ms: Process B (tau 65ms) completed a CPU burst; 49 bursts to go [Q empty]
time 27515ms: Recalculated tau from 65ms to 39ms for process B [Q empty]
time 27515ms: Process B switching out of CPU; will block on I/O until time 27917ms [Q empty]
time 27917ms: Process B (tau 39ms) completed I/O; added to ready queue [Q B]
time 27919ms: Process B (tau 39ms) started using the CPU for 150ms burst [Q empty]
time 28069ms: Process B (tau 39ms) completed a CPU burst; 48 bursts to go [Q empty]
time 28069ms: Recalculated tau from 39ms to 95ms for process B [Q empty]
time 28069ms: Process B switching out of CPU; will block on I/O until time 28151ms [Q empty]
time 28151ms: Process B (tau 95ms) completed I/O; added to ready queue [Q B]
time 28153ms: Process B (tau 95ms) started using the CPU for 33ms burst [Q empty]
time 28186ms: Process B (tau 95ms) completed a CPU burst; 47 bursts to go [Q empty]
time 28186ms: Recalculated tau from 95ms to 65ms for process B [Q empty]
time 28186ms: Process B switching out of CPU; will block on I/O until time 28218ms [Q empty]
time 28218ms: Process B (tau 65ms) completed I/O; added to ready queue [Q B]
time 28220ms: Process B (tau 65ms) started using the CPU for 17ms burst [Q empty]
time 28237ms: Process B (tau 65ms) completed a CPU burst; 46 bursts to go [Q empty]
time 28237ms: Recalculated tau from 65ms to 42ms for process B [Q empty]
time 28237ms: Process B switching out of CPU; will block on I/O until time 28669ms [Q empty]
time 28669ms: Process B (tau 42ms) completed I/O; added to ready queue [Q B]
time 28671ms: Process B (tau 42ms) started using the CPU for 31ms burst [Q empty]
time 28702ms: Process B (tau 42ms) completed a CPU burst; 45 bursts to go [Q empty]
time 28702ms: Recalculated tau from 42ms to 37ms for process B [Q empty]
time 28702ms: Process B switching out of CPU; will block on I/O until time 29024ms [Q empty]
time 29024ms: Process B (tau 37ms) completed I/O; added to ready queue [Q B]
time 29026ms: Process B (tau 37ms) started using the CPU for 102ms burst [Q empty]
time 29128ms: Process B (tau 37ms) completed a CPU burst; 44 bursts to go [Q empty]
time 29128ms: Recalculated tau from 37ms to 70ms for process B [Q empty]
time 29128ms: Process B switching out of CPU; will block on I/O until time 29140ms [Q empty]
time 29140ms: Process B (tau 70ms) completed I/O; added to ready queue [Q B]
time 29142ms: Process B (tau 70ms) started using the CPU for 142ms burst [Q empty]
time 29284ms: Process B (tau 70ms) completed a CPU burst; 43 bursts to go [Q empty]
time 29284ms: Recalculated tau from 70ms to 106ms for process B [Q empty]
time 29284ms: Process B switching out of CPU; will block on I/O until time 30016ms [Q empty]
time 30016ms: Process B (tau 106ms) completed I/O; added to ready queue [Q B]
time 30018ms: Process B (tau 106ms) started using the CPU for 205ms burst [Q empty]
time 30223ms: Process B (tau 106ms) completed a CPU burst; 42 bursts to go [Q empty]
time 30223ms: Recalculated tau from 106ms to 156ms for process B [Q empty]
time 30223ms: Process B switching out of CPU; will block on I/O until time 31715ms [Q empty]
time 31715ms: Process B (tau 156ms) completed I/O; added to ready queue [Q B]
time 31717ms: Process B (tau 156ms) started using the CPU for 72ms burst [Q empty]
time 31789ms: Process B (tau 156ms) completed a CPU burst; 41 bursts to go [Q empty]
time 31789ms: Recalculated tau from 156ms to 114ms for process B [Q empty]
time 31789ms: Process B switching out of CPU; will block on I/O until time 32191ms [Q empty]
time 32191ms: Process B (tau 114ms) completed I/O; added to ready queue [Q B]
time 32193ms: Process B (tau 114ms) started using the CPU for 123ms burst [Q empty]
time 32316ms: Process B (tau 114ms) completed a CPU burst; 40 bursts to go [Q empty]
time 32316ms: Recalculated tau from 114ms to 119ms for process B [Q empty]
time 32316ms: Process B switching out of CPU; will block on I/O until time 32798ms [Q empty]
time 32798ms: Process B (tau 119ms) completed I/O; added to ready queue [Q B]
time 32800ms: Process B (tau 119ms) started using the CPU for 44ms burst [Q empty]
time 32844ms: Process B (tau 119ms) completed a CPU burst; 39 bursts to go [Q empty]
time 32844ms: Recalculated tau from 119ms to 82ms for process B [Q empty]
time 32844ms: Process B switching out of CPU; will block on I/O until time 33096ms [Q empty]
time 33096ms: Process B (tau 82ms) completed I/O; added to ready queue [Q B]
time 33098ms: Process B (tau 82ms) started using the CPU for 58ms burst [Q empty]
time 33156ms: Process B (tau 82ms) completed a CPU burst; 38 bursts to go [Q empty]
time 33156ms: Recalculated tau from 82ms to 70ms for process B [Q empty]
time 33156ms: Process B switching out of CPU; will block on I/O until time 33298ms [Q empty]
time 33298ms: Process B (tau 70ms) completed I/O; added to ready queue [Q B]
time 33300ms: Process B (tau 70ms) started using the CPU for 121ms burst [Q empty]
time 33421ms: Process B (tau 70ms) completed a CPU burst; 37 bursts to go [Q empty]
time 33421ms: Recalculated tau from 70ms to 96ms for process B [Q empty]
time 33421ms: Process B switching out of CPU; will block on I/O until time 35503ms [Q empty]
time 35503ms: Process B (tau 96ms) completed I/O; added to ready queue [Q B]
time 35505ms: Process B (tau 96ms) started using the CPU for 8ms burst [Q empty]
time 35513ms: Process B (tau 96ms) completed a CPU burst; 36 bursts to go [Q empty]
time 35513ms: Recalculated tau from 96ms to 52ms for process B [Q empty]
time 35513ms: Process B switching out of CPU; will block on I/O until time 35575ms [Q empty]
time 35575ms: Process B (tau 52ms) completed I/O; added to ready queue [Q B]
time 35577ms: Process B (tau 52ms) started using the CPU for 137ms burst [Q empty]
time 35714ms: Process B (tau 52ms) completed a CPU burst; 35 bursts to go [Q empty]
time 35714ms: Recalculated tau from 52ms to 95ms for process B [Q empty]
time 35714ms: Process B switching out of CPU; will block on I/O until time 36536ms [Q empty]
time 36536ms: Process B (tau 95ms) completed I/O; added to ready queue [Q B]
time 36538ms: Process B (tau 95ms) started using the CPU for 145ms burst [Q empty]
time 36683ms: Process B (tau 95ms) completed a CPU burst; 34 bursts to go [Q empty]
time 36683ms: Recalculated tau from 95ms to 121ms for process B [Q empty]
time 36683ms: Process B switching out of CPU; will block on I/O until time 39965ms [Q empty]
time 39965ms: Process B (tau 121ms) completed I/O; added to ready queue [Q B]
time 39967ms: Process B (tau 121ms) started using the CPU for 39ms burst [Q empty]
time 40006ms: Process B (tau 121ms) completed a CPU burst; 33 bursts to go [Q empty]
time 40006ms: Recalculated tau from 121ms to 81ms for process B [Q empty]
time 40006ms: Process B switching out of CPU; will block on I/O until time 40848ms [Q empty]
time 40848ms: Process B (tau 81ms) completed I/O; added to ready queue [Q B]
time 40850ms: Process B (tau 81ms) started using the CPU for 24ms burst [Q empty]
time 40874ms: Process B (tau 81ms) completed a CPU burst; 32 bursts to go [Q empty]
time 40874ms: Recalculated tau from 81ms to 53ms for process B [Q empty]
time 40874ms: Process B switching out of CPU; will block on I/O until time 41666ms [Q empty]
time 41666ms: Process B (tau 53ms) completed I/O; added to ready queue [Q B]
time 41668ms: Process B (tau 53ms) started using the CPU for 119ms burst [Q empty]
time 41787ms: Process B (tau 53ms) completed a CPU burst; 31 bursts to go [Q empty]
time 41787ms: Recalculated tau from 53ms to 87ms for process B [Q empty]
time 41787ms: Process B switching out of CPU; will block on I/O until time 43779ms [Q empty]
time 43779ms: Process B (tau 87ms) completed I/O; added to ready queue [Q B]
time 43781ms: Process B (tau 87ms) started using the CPU for 8ms burst [Q empty]
time 43789ms: Process B (tau 87ms) completed a CPU burst; 30 bursts to go [Q empty]
time 43789ms: Recalculated tau from 87ms to 48ms for process B [Q empty]
time 43789ms: Process B switching out of CPU; will block on I/O until time 45291ms [Q empty]
time 45291ms: Process B (tau 48ms) completed I/O; added to ready queue [Q B]
time 45293ms: Process B (tau 48ms) started using the CPU for 136ms burst [Q empty]
time 45429ms: Process B (tau 48ms) completed a CPU burst; 29 bursts to go [Q empty]
time 45429ms: Recalculated tau from 48ms to 92ms for process B [Q empty]
time 45429ms: Process B switching out of CPU; will block on I/O until time 45941ms [Q empty]
time 45941ms: Process B (tau 92ms) completed I/O; added to ready queue [Q B]
time 45943ms: Process B (tau 92ms) started using the CPU for 10ms burst [Q empty]
time 45953ms: Process B (tau 92ms) completed a CPU burst; 28 bursts to go [Q empty]
time 45953ms: Recalculated tau from 92ms to 51ms for process B [Q empty]
time 45953ms: Process B switching out of CPU; will block on I/O until time 47085ms [Q empty]
time 47085ms: Process B (tau 51ms) completed I/O; added to ready queue [Q B]
time 47087ms: Process B (tau 51ms) started using the CPU for 85ms burst [Q empty]
time 47172ms: Process B (tau 51ms) completed a CPU burst; 27 bursts to go [Q empty]
time 47172ms: Recalculated tau from 51ms to 69ms for process B [Q empty]
time 47172ms: Process B switching out of CPU; will block on I/O until time 47674ms [Q empty]
time 47674ms: Process B (tau 69ms) completed I/O; added to ready queue [Q B]
time 47676ms: Process B (tau 69ms) started using the CPU for 318ms burst [Q empty]
time 47994ms: Process B (tau 69ms) completed a CPU burst; 26 bursts to go [Q empty]
time 47994ms: Recalculated tau from 69ms to 194ms for process B [Q empty]
time 47994ms: Process B switching out of CPU; will block on I/O until time 49336ms [Q empty]
time 49336ms: Process B (tau 194ms) completed I/O; added to ready queue [Q B]
time 49338ms: Process B (tau 194ms) started using the CPU for 119ms burst [Q empty]
time 49457ms: Process B (tau 194ms) completed a CPU burst; 25 bursts to go [Q empty]
time 49457ms: Recalculated tau from 194ms to 157ms for process B [Q empty]
time 49457ms: Process B switching out of CPU; will block on I/O until time 51829ms [Q empty]
time 51829ms: Process B (tau 157ms) completed I/O; added to ready queue [Q B]
time 51831ms: Process B (tau 157ms) started using the CPU for 43ms burst [Q empty]
time 51874ms: Process B (tau 157ms) completed a CPU burst; 24 bursts to go [Q empty]
time 51874ms: Recalculated tau from 157ms to 101ms for process B [Q empty]
time 51874ms: Process B switching out of CPU; will block on I/O until time 52496ms [Q empty]
time 52496ms: Process B (tau 101ms) completed I/O; added to ready queue [Q B]
time 52498ms: Process B (tau 101ms) started using the CPU for 126ms burst [Q empty]
time 52624ms: Process B (tau 101ms) completed a CPU burst; 23 bursts to go [Q empty]
time 52624ms: Recalculated tau from 101ms to 114ms for process B [Q empty]
time 52624ms: Process B switching out of CPU; will block on I/O until time 52736ms [Q empty]
time 52736ms: Process B (tau 114ms) completed I/O; added to ready queue [Q B]
time 52738ms: Process B (tau 114ms) started using the CPU for 42ms burst [Q empty]
time 52780ms: Process B (tau 114ms) completed a CPU burst; 22 bursts to go [Q empty]
time 52780ms: Recalculated tau from 114ms to 78ms for process B [Q empty]
time 52780ms: Process B switching out of CPU; will block on I/O until time 52892ms [Q empty]
time 52892ms: Process B (tau 78ms) completed I/O; added to ready queue [Q B]
time 52894ms: Process B (tau 78ms) started using the CPU for 21ms burst [Q empty]
time 52915ms: Process B (tau 78ms) completed a CPU burst; 21 bursts to go [Q empty]
time 52915ms: Recalculated tau from 78ms to 50ms for process B [Q empty]
time 52915ms: Process B switching out of CPU; will block on I/O until time 55457ms [Q empty]
time 55457ms: Process B (tau 50ms) completed I/O; added to ready queue [Q B]
time 55459ms: Process B (tau 50ms) started using the CPU for 140ms burst [Q empty]
time 55599ms: Process B (tau 50ms) completed a CPU burst; 20 bursts to go [Q empty]
time 55599ms: Recalculated tau from 50ms to 95ms for process B [Q empty]
time 55599ms: Process B switching out of CPU; will block on I/O until time 57681ms [Q empty]
time 57681ms: Process B (tau 95ms) completed I/O; added to ready queue [Q B]
time 57683ms: Process B (tau 95ms) started using the CPU for 15ms burst [Q empty]
time 57698ms: Process B (tau 95ms) completed a CPU burst; 19 bursts to go [Q empty]
time 57698ms: Recalculated tau from 95ms to 56ms for process B [Q empty]
time 57698ms: Process B switching out of CPU; will block on I/O until time 58990ms [Q empty]
time 58990ms: Process B (tau 56ms) completed I/O; added to ready queue [Q B]
time 58992ms: Process B (tau 56ms) started using the CPU for 65ms burst [Q empty]
time 59057ms: Process B (tau 56ms) completed a CPU burst; 18 bursts to go [Q empty]
time 59057ms: Recalculated tau from 56ms to 61ms for process B [Q empty]
time 59057ms: Process B switching out of CPU; will block on I/O until time 60149ms [Q empty]
time 60149ms: Process B (tau 61ms) completed I/O; added to ready queue [Q B]
time 60151ms: Process B (tau 61ms) started using the CPU for 34ms burst [Q empty]
time 60185ms: Process B (tau 61ms) completed a CPU burst; 17 bursts to go [Q empty]
time 60185ms: Recalculated tau from 61ms to 48ms for process B [Q empty]
time 60185ms: Process B switching out of CPU; will block on I/O until time 62307ms [Q empty]
time 62307ms: Process B (tau 48ms) completed I/O; added to ready queue [Q B]
time 62309ms: Process B (tau 48ms) started using the CPU for 58ms burst [Q empty]
time 62367ms: Process B (tau 48ms) completed a CPU burst; 16 bursts to go [Q empty]
time 62367ms: Recalculated tau from 48ms to 53ms for process B [Q empty]
time 62367ms: Process B switching out of CPU; will block on I/O until time 62659ms [Q empty]
time 62659ms: Process B (tau 53ms) completed I/O; added to ready queue [Q B]
time 62661ms: Process B (tau 53ms) started using the CPU for 6ms burst [Q empty]
time 62667ms: Process B (tau 53ms) completed a CPU burst; 15 bursts to go [Q empty]
time 62667ms: Recalculated tau from 53ms to 30ms for process B [Q empty]
time 62667ms: Process B switching out of CPU; will block on I/O until time 63239ms [Q empty]
time 63239ms: Process B (tau 30ms) completed I/O; added to ready queue [Q B]
time 63241ms: Process B (tau 30ms) started using the CPU for 14ms burst [Q empty]
time 63255ms: Process B (tau 30ms) completed a CPU burst; 14 bursts to go [Q empty]
time 63255ms: Recalculated tau from 30ms to 22ms for process B [Q empty]
time 63255ms: Process B switching out of CPU; will block on I/O until time 63847ms [Q empty]
time 63847ms: Process B (tau 22ms) completed I/O; added to ready queue [Q B]
time 63849ms: Process B (tau 22ms) started using the CPU for 156ms burst [Q empty]
time 64005ms: Process B (tau 22ms) completed a CPU burst; 13 bursts to go [Q empty]
time 64005ms: Recalculated tau from 22ms to 89ms for process B [Q empty]
time 64005ms: Process B switching out of CPU; will block on I/O until time 64257ms [Q empty]
time 64257ms: Process B (tau 89ms) completed I/O; added to ready queue [Q B]
time 64259ms: Process B (tau 89ms) started using the CPU for 107ms burst [Q empty]
time 64366ms: Process B (tau 89ms) completed a CPU burst; 12 bursts to go [Q empty]
time 64366ms: Recalculated tau from 89ms to 99ms for process B [Q empty]
time 64366ms: Process B switching out of CPU; will block on I/O until time 64818ms [Q empty]
time 64818ms: Process B (tau 99ms) completed I/O; added to ready queue [Q B]
time 64820ms: Process B (tau 99ms) started using the CPU for 41ms burst [Q empty]
time 64861ms: Process B (tau 99ms) completed a CPU burst; 11 bursts to go [Q empty]
time 64861ms: Recalculated tau from 99ms to 71ms for process B [Q empty]
time 64861ms: Process B switching out of CPU; will block on I/O until time 64893ms [Q empty]
time 64893ms: Process B (tau 71ms) completed I/O; added to ready queue [Q B]
time 64895ms: Process B (tau 71ms) started using the CPU for 36ms burst [Q empty]
time 64931ms: Process B (tau 71ms) completed a CPU burst; 10 bursts to go [Q empty]
time 64931ms: Recalculated tau from 71ms to 54ms for process B [Q empty]
time 64931ms: Process B switching out of CPU; will block on I/O until time 65713ms [Q empty]
time 65713ms: Process B (tau 54ms) completed I/O; added to ready queue [Q B]
time 65715ms: Process B (tau 54ms) started using the CPU for 228ms burst [Q empty]
time 65943ms: Process B (tau 54ms) completed a CPU burst; 9 bursts to go [Q empty]
time 65943ms: Recalculated tau from 54ms to 141ms for process B [Q empty]
time 65943ms: Process B switching out of CPU; will block on I/O until time 66115ms [Q empty]
time 66115ms: Process B (tau 141ms) completed I/O; added to ready queue [Q B]
time 66117ms: Process B (tau 141ms) started using the CPU for 137ms burst [Q empty]
time 66254ms: Process B (tau 141ms) completed a CPU burst; 8 bursts to go [Q empty]
time 66254ms: Recalculated tau from 141ms to 140ms for process B [Q empty]
time 66254ms: Process B switching out of CPU; will block on I/O until time 66576ms [Q empty]
time 66576ms: Process B (tau 140ms) completed I/O; added to ready queue [Q B]
time 66578ms: Process B (tau 140ms) started using the CPU for 167ms burst [Q empty]
time 66745ms: Process B (tau 140ms) completed a CPU burst; 7 bursts to go [Q empty]
time 66745ms: Recalculated tau from 140ms to 154ms for process B [Q empty]
time 66745ms: Process B switching out of CPU; will block on I/O until time 67697ms [Q empty]
time 67697ms: Process B (tau 154ms) completed I/O; added to ready queue [Q B]
time 67699ms: Process B (tau 154ms) started using the CPU for 25ms burst [Q empty]
time 67724ms: Process B (tau 154ms) completed a CPU burst; 6 bursts to go [Q empty]
time 67724ms: Recalculated tau from 154ms to 90ms for process B [Q empty]
time 67724ms: Process B switching out of CPU; will block on I/O until time 68906ms [Q empty]
time 68906ms: Process B (tau 90ms) completed I/O; added to ready queue [Q B]
time 68908ms: Process B (tau 90ms) started using the CPU for 109ms burst [Q empty]
time 69017ms: Process B (tau 90ms) completed a CPU burst; 5 bursts to go [Q empty]
time 69017ms: Recalculated tau from 90ms to 100ms for process B [Q empty]
time 69017ms: Process B switching out of CPU; will block on I/O until time 70109ms [Q empty]
time 70109ms: Process B (tau 100ms) completed I/O; added to ready queue [Q B]
time 70111ms: Process B (tau 100ms) started using the CPU for 197ms burst [Q empty]
time 70308ms: Process B (tau 100ms) completed a CPU burst; 4 bursts to go [Q empty]
time 70308ms: Recalculated tau from 100ms to 149ms for process B [Q empty]
time 70308ms: Process B switching out of CPU; will block on I/O until time 72580ms [Q empty]
time 72580ms: Process B (tau 149ms) completed I/O; added to ready queue [Q B]
time 72582ms: Process B (tau 149ms) started using the CPU for 292ms burst [Q empty]
time 72874ms: Process B (tau 149ms) completed a CPU burst; 3 bursts to go [Q empty]
time 72874ms: Recalculated tau from 149ms to 221ms for process B [Q empty]
time 72874ms: Process B switching out of CPU; will block on I/O until time 73366ms [Q empty]
time 73366ms: Process B (tau 221ms) completed I/O; added to ready queue [Q B]
time 73368ms: Process B (tau 221ms) started using the CPU for 12ms burst [Q empty]
time 73380ms: Process B (tau 221ms) completed a CPU burst; 2 bursts to go [Q empty]
time 73380ms: Recalculated tau from 221ms to 117ms for process B [Q empty]
time 73380ms: Process B switching out of CPU; will block on I/O until time 73992ms [Q empty]
time 73992ms: Process B (tau 117ms) completed I/O; added to ready queue [Q B]
time 73994ms: Process B (tau 117ms) started using the CPU for 299ms burst [Q empty]
time 74293ms: Process B (tau 117ms) completed a CPU burst; 1 burst to go [Q empty]
time 74293ms: Recalculated tau from 117ms to 209ms for process B [Q empty]
time 74293ms: Process B switching out of CPU; will block on I/O until time 75745ms [Q empty]
time 75745ms: Process B (tau 209ms) completed I/O; added to ready queue [Q B]
time 75747ms: Process B (tau 209ms) started using the CPU for 3ms burst [Q empty]
time 75750ms: Process B terminated [Q empty]
time 75752ms: Simulator ended for SJF [Q empty]

time 0ms: Simulator started for SRT [Q empty]
time 399ms: Process B (tau 100ms) arrived; added to ready queue [Q B]
time 401ms: Process B (tau 100ms) started using the CPU for 338ms burst [Q empty]
time 482ms: Process A (tau 100ms) arrived; added to ready queue [Q A]
time 739ms: Process B (tau 100ms) completed a CPU burst; 69 bursts to go [Q A]
time 739ms: Recalculated tau from 100ms to 219ms for process B [Q A]
time 739ms: Process B switching out of CPU; will block on I/O until time 911ms [Q A]
time 743ms: Process A (tau 100ms) started using the CPU for 30ms burst [Q empty]
time 773ms: Process A (tau 100ms) completed a CPU burst; 9 bursts to go [Q empty]
time 773ms: Recalculated tau from 100ms to 65ms for process A [Q empty]
time 773ms: Process A switching out of CPU; will block on I/O until time 3595ms [Q empty]
time 911ms: Process B (tau 219ms) completed I/O; added to ready queue [Q B]
time 913ms: Process B (tau 219ms) started using the CPU for 95ms burst [Q empty]
time 1008ms: Process B (tau 219ms) completed a CPU burst; 68 bursts to go [Q empty]
time 1008ms: Recalculated tau from 219ms to 158ms for process B [Q empty]
time 1008ms: Process B switching out of CPU; will block on I/O until time 3570ms [Q empty]
time 3570ms: Process B (tau 158ms) completed I/O; added to ready queue [Q B]
time 3572ms: Process B (tau 158ms) started using the CPU for 324ms burst [Q empty]
time 3595ms: Process A (tau 65ms) completed I/O; preempting B [Q A]
time 3599ms: Process A (tau 65ms) started using the CPU for 76ms burst [Q B]
time 3675ms: Process A (tau 65ms) completed a CPU burst; 8 bursts to go [Q B]
time 3675ms: Recalculated tau from 65ms to 71ms for process A [Q B]
time 3675ms: Process A switching out of CPU; will block on I/O until time 3997ms [Q B]
time 3679ms: Process B (tau 158ms) started using the CPU for remaining 301ms of 324ms burst [Q empty]
time 3980ms: Process B (tau 158ms) completed a CPU burst; 67 bursts to go [Q empty]
time 3980ms: Recalculated tau from 158ms to 241ms for process B [Q empty]
time 3980ms: Process B switching out of CPU; will block on I/O until time 5092ms [Q empty]
time 3997ms: Process A (tau 71ms) completed I/O; added to ready queue [Q A]
time 3999ms: Process A (tau 71ms) started using the CPU for 190ms burst [Q empty]
time 4189ms: Process A (tau 71ms) completed a CPU burst; 7 bursts to go [Q empty]
time 4189ms: Recalculated tau from 71ms to 131ms for process A [Q empty]
time 4189ms: Process A switching out of CPU; will block on I/O until time 4231ms [Q empty]
time 4231ms: Process A (tau 131ms) completed I/O; added to ready queue [Q A]
time 4233ms: Process A (tau 131ms) started using the CPU for 28ms burst [Q empty]
time 4261ms: Process A (tau 131ms) completed a CPU burst; 6 bursts to go [Q empty]
time 4261ms: Recalculated tau from 131ms to 80ms for process A [Q empty]
time 4261ms: Process A switching out of CPU; will block on I/O until time 5363ms [Q empty]
time 5092ms: Process B (tau 241ms) completed I/O; added to ready queue [Q B]
time 5094ms: Process B (tau 241ms) started using the CPU for 451ms burst [Q empty]
time 5363ms: Process A (tau 80ms) completed I/O; added to ready queue [Q A]
time 5545ms: Process B (tau 241ms) completed a CPU burst; 66 bursts to go [Q A]
time 5545ms: Recalculated tau from 241ms to 347ms for process B [Q A]
time 5545ms: Process B switching out of CPU; will block on I/O until time 5697ms [Q A]
time 5549ms: Process A (tau 80ms) started using the CPU for 53ms burst [Q empty]
time 5602ms: Process A (tau 80ms) completed a CPU burst; 5 bursts to go [Q empty]
time 5602ms: Recalculated tau from 80ms to 67ms for process A [Q empty]
time 5602ms: Process A switching out of CPU; will block on I/O until time 6714ms [Q empty]
time 5697ms: Process B (tau 347ms) completed I/O; added to ready queue [Q B]
time 5699ms: Process B (tau 347ms) started using the CPU for 57ms burst [Q empty]
time 5756ms: Process B (tau 347ms) completed a CPU burst; 65 bursts to go [Q empty]
time 5756ms: Recalculated tau from 347ms to 203ms for process B [Q empty]
time 5756ms: Process B switching out of CPU; will block on I/O until time 6828ms [Q empty]
time 6714ms: Process A (tau 67ms) completed I/O; added to ready queue [Q A]
time 6716ms: Process A (tau 67ms) started using the CPU for 111ms burst [Q empty]
time 6827ms: Process A (tau 67ms) completed a CPU burst; 4 bursts to go [Q empty]
time 6827ms: Recalculated tau from 67ms to 90ms for process A [Q empty]
time 6827ms: Process A switching out of CPU; will block on I/O until time 7539ms [Q empty]
time 6828ms: Process B (tau 203ms) completed I/O; added to ready queue [Q B]
time 6831ms: Process B (tau 203ms) started using the CPU for 244ms burst [Q empty]
time 7075ms: Process B (tau 203ms) completed a CPU burst; 64 bursts to go [Q empty]
time 7075ms: Recalculated tau from 203ms to 224ms for process B [Q empty]
time 7075ms: Process B switching out of CPU; will block on I/O until time 8157ms [Q empty]
time 7539ms: Process A (tau 90ms) completed I/O; added to ready queue [Q A]
time 7541ms: Process A (tau 90ms) started using the CPU for 91ms burst [Q empty]
time 7632ms: Process A (tau 90ms) completed a CPU burst; 3 bursts to go [Q empty]
time 7632ms: Recalculated tau from 90ms to 91ms for process A [Q empty]
time 7632ms: Process A switching out of CPU; will block on I/O until time 9424ms [Q empty]
time 8157ms: Process B (tau 224ms) completed I/O; added to ready queue [Q B]
time 8159ms: Process B (tau 224ms) started using the CPU for 84ms burst [Q empty]
time 8243ms: Process B (tau 224ms) completed a CPU burst; 63 bursts to go [Q empty]
time 8243ms: Recalculated tau from 224ms to 154ms for process B [Q empty]
time 8243ms: Process B switching out of CPU; will block on I/O until time 8415ms [Q empty]
time 8415ms: Process B (tau 154ms) completed I/O; added to ready queue [Q B]
time 8417ms: Process B (tau 154ms) started using the CPU for 65ms burst [Q empty]
time 8482ms: Process B (tau 154ms) completed a CPU burst; 62 bursts to go [Q empty]
time 8482ms: Recalculated tau from 154ms to 110ms for process B [Q empty]
time 8482ms: Process B switching out of CPU; will block on I/O until time 8974ms [Q empty]
time 8974ms: Process B (tau 110ms) completed I/O; added to ready queue [Q B]
time 8976ms: Process B (tau 110ms) started using the CPU for 55ms burst [Q empty]
time 9031ms: Process B (tau 110ms) completed a CPU burst; 61 bursts to go [Q empty]
time 9031ms: Recalculated tau from 110ms to 83ms for process B [Q empty]
time 9031ms: Process B switching out of CPU; will block on I/O until time 9543ms [Q empty]
time 9424ms: Process A (tau 91ms) completed I/O; added to ready queue [Q A]
time 9426ms: Process A (tau 91ms) started using the CPU for 70ms burst [Q empty]
time 9496ms: Process A (tau 91ms) completed a CPU burst; 2 bursts to go [Q empty]
time 9496ms: Recalculated tau from 91ms to 81ms for process A [Q empty]
time 9496ms: Process A switching out of CPU; will block on I/O until time 10578ms [Q empty]
time 9543ms: Process B (tau 83ms) completed I/O; added to ready queue [Q B]
time 9545ms: Process B (tau 83ms) started using the CPU for 71ms burst [Q empty]
time 9616ms: Process B (tau 83ms) completed a CPU burst; 60 bursts to go [Q empty]
time 9616ms: Recalculated tau from 83ms to 78ms for process B [Q empty]
time 9616ms: Process B switching out of CPU; will block on I/O until time 10578ms [Q empty]
time 10578ms: Process A (tau 81ms) completed I/O; added to ready queue [Q A]
time 10578ms: Process B (tau 78ms) completed I/O; added to ready queue [Q BA]
time 10580ms: Process B (tau 78ms) started using the CPU for 20ms burst [Q A]
time 10600ms: Process B (tau 78ms) completed a CPU burst; 59 bursts to go [Q A]
time 10600ms: Recalculated tau from 78ms to 49ms for process B [Q A]
time 10600ms: Process B switching out of CPU; will block on I/O until time 11452ms [Q A]
time 10604ms: Process A (tau 81ms) started using the CPU for 63ms burst [Q empty]
time 10667ms: Process A (tau 81ms) completed a CPU burst; 1 burst to go [Q empty]
time 10667ms: Recalculated tau from 81ms to 73ms for process A [Q empty]
time 10667ms: Process A switching out of CPU; will block on I/O until time 11189ms [Q empty]
time 11189ms: Process A (tau 73ms) completed I/O; added to ready queue [Q A]
time 11191ms: Process A (tau 73ms) started using the CPU for 5ms burst [Q empty]
time 11196ms: Process A terminated [Q empty]
time 11452ms: Process B (tau 49ms) completed I/O; added to ready queue [Q B]
time 11454ms: Process B (tau 49ms) started using the CPU for 182ms burst [Q empty]
time 11636ms: Process B (tau 49ms) completed a CPU burst; 58 bursts to go [Q empty]
time 11636ms: Recalculated tau from 49ms to 116ms for process B [Q empty]
time 11636ms: Process B switching out of CPU; will block on I/O until time 13818ms [Q empty]
time 13818ms: Process B (tau 116ms) completed I/O; added to ready queue [Q B]
time 13820ms: Process B (tau 116ms) started using the CPU for 190ms burst [Q empty]
time 14010ms: Process B (tau 116ms) completed a CPU burst; 57 bursts to go [Q empty]
time 14010ms: Recalculated tau from 116ms to 153ms for process B [Q empty]
time 14010ms: Process B switching out of CPU; will block on I/O until time 15462ms [Q empty]
time 15462ms: Process B (tau 153ms) completed I/O; added to ready queue [Q B]
time 15464ms: Process B (tau 153ms) started using the CPU for 239ms burst [Q empty]
time 15703ms: Process B (tau 153ms) completed a CPU burst; 56 bursts to go [Q empty]
time 15703ms: Recalculated tau from 153ms to 197ms for process B [Q empty]
time 15703ms: Process B switching out of CPU; will block on I/O until time 19515ms [Q empty]
time 19515ms: Process B (tau 197ms) completed I/O; added to ready queue [Q B]
time 19517ms: Process B (tau 197ms) started using the CPU for 274ms burst [Q empty]
time 19791ms: Process B (tau 197ms) completed a CPU burst; 55 bursts to go [Q empty]
time 19791ms: Recalculated tau from 197ms to 236ms for process B [Q empty]
time 19791ms: Process B switching out of CPU; will block on I/O until time 20163ms [Q empty]
time 20163ms: Process B (tau 236ms) completed I/O; added to ready queue [Q B]
time 20165ms: Process B (tau 236ms) started using the CPU for 19ms burst [Q empty]
time 20184ms: Process B (tau 236ms) completed a CPU burst; 54 bursts to go [Q empty]
time 20184ms: Recalculated tau from 236ms to 128ms for process B [Q empty]
time 20184ms: Process B switching out of CPU; will block on I/O until time 21166ms [Q empty]
time 21166ms: Process B (tau 128ms) completed I/O; added to ready queue [Q B]
time 21168ms: Process B (tau 128ms) started using the CPU for 54ms burst [Q empty]
time 21222ms: Process B (tau 128ms) completed a CPU burst; 53 bursts to go [Q empty]
time 21222ms: Recalculated tau from 128ms to 91ms for process B [Q empty]
time 21222ms: Process B switching out of CPU; will block on I/O until time 21474ms [Q empty]
time 21474ms: Process B (tau 91ms) completed I/O; added to ready queue [Q B]
time 21476ms: Process B (tau 91ms) started using the CPU for 54ms burst [Q empty]
time 21530ms: Process B (tau 91ms) completed a CPU burst; 52 bursts to go [Q empty]
time 21530ms: Recalculated tau from 91ms to 73ms for process B [Q empty]
time 21530ms: Process B switching out of CPU; will block on I/O until time 21712ms [Q empty]
time 21712ms: Process B (tau 73ms) completed I/O; added to ready queue [Q B]
time 21714ms: Process B (tau 73ms) started using the CPU for 131ms burst [Q empty]
time 21845ms: Process B (tau 73ms) completed a CPU burst; 51 bursts to go [Q empty]
time 21845ms: Recalculated tau from 73ms to 103ms for process B [Q empty]
time 21845ms: Process B switching out of CPU; will block on I/O until time 23717ms [Q empty]
time 23717ms: Process B (tau 103ms) completed I/O; added to ready queue [Q B]
time 23719ms: Process B (tau 103ms) started using the CPU for 26ms burst [Q empty]
time 23745ms: Process B (tau 103ms) completed a CPU burst; 50 bursts to go [Q empty]
time 23745ms: Recalculated tau from 103ms to 65ms for process B [Q empty]
time 23745ms: Process B switching out of CPU; will block on I/O until time 27587ms [Q empty]
time 27587ms: Process B (tau 65ms) completed I/O; added to ready queue [Q B]
time 27589ms: Process B (tau 65ms) started using the CPU for 11ms burst [Q empty]
time 27600ms: Process B (tau 65ms) completed a CPU burst; 49 bursts to go [Q empty]
time 27600ms: Recalculated tau from 65ms to 39ms for process B [Q empty]
time 27600ms: Process B switching out of CPU; will block on I/O until time 28002ms [Q empty]
time 28002ms: Process B (tau 39ms) completed I/O; added to ready queue [Q B]
time 28004ms: Process B (tau 39ms) started using the CPU for 150ms burst [Q empty]
time 28154ms: Process B (tau 39ms) completed a CPU burst; 48 bursts to go [Q empty]
time 28154ms: Recalculated tau from 39ms to 95ms for process B [Q empty]
time 28154ms: Process B switching out of CPU; will block on I/O until time 28236ms [Q empty]
time 28236ms: Process B (tau 95ms) completed I/O; added to ready queue [Q B]
time 28238ms: Process B (tau 95ms) started using the CPU for 33ms burst [Q empty]
time 28271ms: Process B (tau 95ms) completed a CPU burst; 47 bursts to go [Q empty]
time 28271ms: Recalculated tau from 95ms to 65ms for process B [Q empty]
time 28271ms: Process B switching out of CPU; will block on I/O until time 28303ms [Q empty]
time 28303ms: Process B (tau 65ms) completed I/O; added to ready queue [Q B]
time 28305ms: Process B (tau 65ms) started using the CPU for 17ms burst [Q empty]
time 28322ms: Process B (tau 65ms) completed a CPU burst; 46 bursts to go [Q empty]
time 28322ms: Recalculated tau from 65ms to 42ms for process B [Q empty]
time 28322ms: Process B switching out of CPU; will block on I/O until time 28754ms [Q empty]
time 28754ms: Process B (tau 42ms) completed I/O; added to ready queue [Q B]
time 28756ms: Process B (tau 42ms) started using the CPU for 31ms burst [Q empty]
time 28787ms: Process B (tau 42ms) completed a CPU burst; 45 bursts to go [Q empty]
time 28787ms: Recalculated tau from 42ms to 37ms for process B [Q empty]
time 28787ms: Process B switching out of CPU; will block on I/O until time 29109ms [Q empty]
time 29109ms: Process B (tau 37ms) completed I/O; added to ready queue [Q B]
time 29111ms: Process B (tau 37ms) started using the CPU for 102ms burst [Q empty]
time 29213ms: Process B (tau 37ms) completed a CPU burst; 44 bursts to go [Q empty]
time 29213ms: Recalculated tau from 37ms to 70ms for process B [Q empty]
time 29213ms: Process B switching out of CPU; will block on I/O until time 29225ms [Q empty]
time 29225ms: Process B (tau 70ms) completed I/O; added to ready queue [Q B]
time 29227ms: Process B (tau 70ms) started using the CPU for 142ms burst [Q empty]
time 29369ms: Process B (tau 70ms) completed a CPU burst; 43 bursts to go [Q empty]
time 29369ms: Recalculated tau from 70ms to 106ms for process B [Q empty]
time 29369ms: Process B switching out of CPU; will block on I/O until time 30101ms [Q empty]
time 30101ms: Process B (tau 106ms) completed I/O; added to ready queue [Q B]
time 30103ms: Process B (tau 106ms) started using the CPU for 205ms burst [Q empty]
time 30308ms: Process B (tau 106ms) completed a CPU burst; 42 bursts to go [Q empty]
time 30308ms: Recalculated tau from 106ms to 156ms for process B [Q empty]
time 30308ms: Process B switching out of CPU; will block on I/O until time 31800ms [Q empty]
time 31800ms: Process B (tau 156ms) completed I/O; added to ready queue [Q B]
time 31802ms: Process B (tau 156ms) started using the CPU for 72ms burst [Q empty]
time 31874ms: Process B (tau 156ms) completed a CPU burst; 41 bursts to go [Q empty]
time 31874ms: Recalculated tau from 156ms to 114ms for process B [Q empty]
time 31874ms: Process B switching out of CPU; will block on I/O until time 32276ms [Q empty]
time 32276ms: Process B (tau 114ms) completed I/O; added to ready queue [Q B]
time 32278ms: Process B (tau 114ms) started using the CPU for 123ms burst [Q empty]
time 32401ms: Process B (tau 114ms) completed a CPU burst; 40 bursts to go [Q empty]
time 32401ms: Recalculated tau from 114ms to 119ms for process B [Q empty]
time 32401ms: Process B switching out of CPU; will block on I/O until time 32883ms [Q empty]
time 32883ms: Process B (tau 119ms) completed I/O; added to ready queue [Q B]
time 32885ms: Process B (tau 119ms) started using the CPU for 44ms burst [Q empty]
time 32929ms: Process B (tau 119ms) completed a CPU burst; 39 bursts to go [Q empty]
time 32929ms: Recalculated tau from 119ms to 82ms for process B [Q empty]
time 32929ms: Process B switching out of CPU; will block on I/O until time 33181ms [Q empty]
time 33181ms: Process B (tau 82ms) completed I/O; added to ready queue [Q B]
time 33183ms: Process B (tau 82ms) started using the CPU for 58ms burst [Q empty]
time 33241ms: Process B (tau 82ms) completed a CPU burst; 38 bursts to go [Q empty]
time 33241ms: Recalculated tau from 82ms to 70ms for process B [Q empty]
time 33241ms: Process B switching out of CPU; will block on I/O until time 33383ms [Q empty]
time 33383ms: Process B (tau 70ms) completed I/O; added to ready queue [Q B]
time 33385ms: Process B (tau 70ms) started using the CPU for 121ms burst [Q empty]
time 33506ms: Process B (tau 70ms) completed a CPU burst; 37 bursts to go [Q empty]
time 33506ms: Recalculated tau from 70ms to 96ms for process B [Q empty]
time 33506ms: Process B switching out of CPU; will block on I/O until time 35588ms [Q empty]
time 35588ms: Process B (tau 96ms) completed I/O; added to ready queue [Q B]
time 35590ms: Process B (tau 96ms) started using the CPU for 8ms burst [Q empty]
time 35598ms: Process B (tau 96ms) completed a CPU burst; 36 bursts to go [Q empty]
time 35598ms: Recalculated tau from 96ms to 52ms for process B [Q empty]
time 35598ms: Process B switching out of CPU; will block on I/O until time 35660ms [Q empty]
time 35660ms: Process B (tau 52ms) completed I/O; added to ready queue [Q B]
time 35662ms: Process B (tau 52ms) started using the CPU for 137ms burst [Q empty]
time 35799ms: Process B (tau 52ms) completed a CPU burst; 35 bursts to go [Q empty]
time 35799ms: Recalculated tau from 52ms to 95ms for process B [Q empty]
time 35799ms: Process B switching out of CPU; will block on I/O until time 36621ms [Q empty]
time 36621ms: Process B (tau 95ms) completed I/O; added to ready queue [Q B]
time 36623ms: Process B (tau 95ms) started using the CPU for 145ms burst [Q empty]
time 36768ms: Process B (tau 95ms) completed a CPU burst; 34 bursts to go [Q empty]
time 36768ms: Recalculated tau from 95ms to 121ms for process B [Q empty]
time 36768ms: Process B switching out of CPU; will block on I/O until time 40050ms [Q empty]
time 40050ms: Process B (tau 121ms) completed I/O; added to ready queue [Q B]
time 40052ms: Process B (tau 121ms) started using the CPU for 39ms burst [Q empty]
time 40091ms: Process B (tau 121ms) completed a CPU burst; 33 bursts to go [Q empty]
time 40091ms: Recalculated tau from 121ms to 81ms for process B [Q empty]
time 40091ms: Process B switching out of CPU; will block on I/O until time 40933ms [Q empty]
time 40933ms: Process B (tau 81ms) completed I/O; added to ready queue [Q B]
time 40935ms: Process B (tau 81ms) started using the CPU for 24ms burst [Q empty]
time 40959ms: Process B (tau 81ms) completed a CPU burst; 32 bursts to go [Q empty]
time 40959ms: Recalculated tau from 81ms to 53ms for process B [Q empty]
time 40959ms: Process B switching out of CPU; will block on I/O until time 41751ms [Q empty]
time 41751ms: Process B (tau 53ms) completed I/O; added to ready queue [Q B]
time 41753ms: Process B (tau 53ms) started using the CPU for 119ms burst [Q empty]
time 41872ms: Process B (tau 53ms) completed a CPU burst; 31 bursts to go [Q empty]
time 41872ms: Recalculated tau from 53ms to 87ms for process B [Q empty]
time 41872ms: Process B switching out of CPU; will block on I/O until time 43864ms [Q empty]
time 43864ms: Process B (tau 87ms) completed I/O; added to ready queue [Q B]
time 43866ms: Process B (tau 87ms) started using the CPU for 8ms burst [Q empty]
time 43874ms: Process B (tau 87ms) completed a CPU burst; 30 bursts to go [Q empty]
time 43874ms: Recalculated tau from 87ms to 48ms for process B [Q empty]
time 43874ms: Process B switching out of CPU; will block on I/O until time 45376ms [Q empty]
time 45376ms: Process B (tau 48ms) completed I/O; added to ready queue [Q B]
time 45378ms: Process B (tau 48ms) started using the CPU for 136ms burst [Q empty]
time 45514ms: Process B (tau 48ms) completed a CPU burst; 29 bursts to go [Q empty]
time 45514ms: Recalculated tau from 48ms to 92ms for process B [Q empty]
time 45514ms: Process B switching out of CPU; will block on I/O until time 46026ms [Q empty]
time 46026ms: Process B (tau 92ms) completed I/O; added to ready queue [Q B]
time 46028ms: Process B (tau 92ms) started using the CPU for 10ms burst [Q empty]
time 46038ms: Process B (tau 92ms) completed a CPU burst; 28 bursts to go [Q empty]
time 46038ms: Recalculated tau from 92ms to 51ms for process B [Q empty]
time 46038ms: Process B switching out of CPU; will block on I/O until time 47170ms [Q empty]
time 47170ms: Process B (tau 51ms) completed I/O; added to ready queue [Q B]
time 47172ms: Process B (tau 51ms) started using the CPU for 85ms burst [Q empty]
time 47257ms: Process B (tau 51ms) completed a CPU burst; 27 bursts to go [Q empty]
time 47257ms: Recalculated tau from 51ms to 69ms for process B [Q empty]
time 47257ms: Process B switching out of CPU; will block on I/O until time 47759ms [Q empty]
time 47759ms: Process B (tau 69ms) completed I/O; added to ready queue [Q B]
time 47761ms: Process B (tau 69ms) started using the CPU for 318ms burst [Q empty]
time 48079ms: Process B (tau 69ms) completed a CPU burst; 26 bursts to go [Q empty]
time 48079ms: Recalculated tau from 69ms to 194ms for process B [Q empty]
time 48079ms: Process B switching out of CPU; will block on I/O until time 49421ms [Q empty]
time 49421ms: Process B (tau 194ms) completed I/O; added to ready queue [Q B]
time 49423ms: Process B (tau 194ms) started using the CPU for 119ms burst [Q empty]
time 49542ms: Process B (tau 194ms) completed a CPU burst; 25 bursts to go [Q empty]
time 49542ms: Recalculated tau from 194ms to 157ms for process B [Q empty]
time 49542ms: Process B switching out of CPU; will block on I/O until time 51914ms [Q empty]
time 51914ms: Process B (tau 157ms) completed I/O; added to ready queue [Q B]
time 51916ms: Process B (tau 157ms) started using the CPU for 43ms burst [Q empty]
time 51959ms: Process B (tau 157ms) completed a CPU burst; 24 bursts to go [Q empty]
time 51959ms: Recalculated tau from 157ms to 101ms for process B [Q empty]
time 51959ms: Process B switching out of CPU; will block on I/O until time 52581ms [Q empty]
time 52581ms: Process B (tau 101ms) completed I/O; added to ready queue [Q B]
time 52583ms: Process B (tau 101ms) started using the CPU for 126ms burst [Q empty]
time 52709ms: Process B (tau 101ms) completed a CPU burst; 23 bursts to go [Q empty]
time 52709ms: Recalculated tau from 101ms to 114ms for process B [Q empty]
time 52709ms: Process B switching out of CPU; will block on I/O until time 52821ms [Q empty]
time 52821ms: Process B (tau 114ms) completed I/O; added to ready queue [Q B]
time 52823ms: Process B (tau 114ms) started using the CPU for 42ms burst [Q empty]
time 52865ms: Process B (tau 114ms) completed a CPU burst; 22 bursts to go [Q empty]
time 52865ms: Recalculated tau from 114ms to 78ms for process B [Q empty]
time 52865ms: Process B switching out of CPU; will block on I/O until time 52977ms [Q empty]
time 52977ms: Process B (tau 78ms) completed I/O; added to ready queue [Q B]
time 52979ms: Process B (tau 78ms) started using the CPU for 21ms burst [Q empty]
time 53000ms: Process B (tau 78ms) completed a CPU burst; 21 bursts to go [Q empty]
time 53000ms: Recalculated tau from 78ms to 50ms for process B [Q empty]
time 53000ms: Process B switching out of CPU; will block on I/O until time 55542ms [Q empty]
time 55542ms: Process B (tau 50ms) completed I/O; added to ready queue [Q B]
time 55544ms: Process B (tau 50ms) started using the CPU for 140ms burst [Q empty]
time 55684ms: Process B (tau 50ms) completed a CPU burst; 20 bursts to go [Q empty]
time 55684ms: Recalculated tau from 50ms to 95ms for process B [Q empty]
time 55684ms: Process B switching out of CPU; will block on I/O until time 57766ms [Q empty]
time 57766ms: Process B (tau 95ms) completed I/O; added to ready queue [Q B]
time 57768ms: Process B (tau 95ms) started using the CPU for 15ms burst [Q empty]
time 57783ms: Process B (tau 95ms) completed a CPU burst; 19 bursts to go [Q empty]
time 57783ms: Recalculated tau from 95ms to 56ms for process B [Q empty]
time 57783ms: Process B switching out of CPU; will block on I/O until time 59075ms [Q empty]
time 59075ms: Process B (tau 56ms) completed I/O; added to ready queue [Q B]
time 59077ms: Process B (tau 56ms) started using the CPU for 65ms burst [Q empty]
time 59142ms: Process B (tau 56ms) completed a CPU burst; 18 bursts to go [Q empty]
time 59142ms: Recalculated tau from 56ms to 61ms for process B [Q empty]
time 59142ms: Process B switching out of CPU; will block on I/O until time 60234ms [Q empty]
time 60234ms: Process B (tau 61ms) completed I/O; added to ready queue [Q B]
time 60236ms: Process B (tau 61ms) started using the CPU for 34ms burst [Q empty]
time 60270ms: Process B (tau 61ms) completed a CPU burst; 17 bursts to go [Q empty]
time 60270ms: Recalculated tau from 61ms to 48ms for process B [Q empty]
time 60270ms: Process B switching out of CPU; will block on I/O until time 62392ms [Q empty]
time 62392ms: Process B (tau 48ms) completed I/O; added to ready queue [Q B]
time 62394ms: Process B (tau 48ms) started using the CPU for 58ms burst [Q empty]
time 62452ms: Process B (tau 48ms) completed a CPU burst; 16 bursts to go [Q empty]
time 62452ms: Recalculated tau from 48ms to 53ms for process B [Q empty]
time 62452ms: Process B switching out of CPU; will block on I/O until time 62744ms [Q empty]
time 62744ms: Process B (tau 53ms) completed I/O; added to ready queue [Q B]
time 62746ms: Process B (tau 53ms) started using the CPU for 6ms burst [Q empty]
time 62752ms: Process B (tau 53ms) completed a CPU burst; 15 bursts to go [Q empty]
time 62752ms: Recalculated tau from 53ms to 30ms for process B [Q empty]
time 62752ms: Process B switching out of CPU; will block on I/O until time 63324ms [Q empty]
time 63324ms: Process B (tau 30ms) completed I/O; added to ready queue [Q B]
time 63326ms: Process B (tau 30ms) started using the CPU for 14ms burst [Q empty]
time 63340ms: Process B (tau 30ms) completed a CPU burst; 14 bursts to go [Q empty]
time 63340ms: Recalculated tau from 30ms to 22ms for process B [Q empty]
time 63340ms: Process B switching out of CPU; will block on I/O until time 63932ms [Q empty]
time 63932ms: Process B (tau 22ms) completed I/O; added to ready queue [Q B]
time 63934ms: Process B (tau 22ms) started using the CPU for 156ms burst [Q empty]
time 64090ms: Process B (tau 22ms) completed a CPU burst; 13 bursts to go [Q empty]
time 64090ms: Recalculated tau from 22ms to 89ms for process B [Q empty]
time 64090ms: Process B switching out of CPU; will block on I/O until time 64342ms [Q empty]
time 64342ms: Process B (tau 89ms) completed I/O; added to ready queue [Q B]
time 64344ms: Process B (tau 89ms) started using the CPU for 107ms burst [Q empty]
time 64451ms: Process B (tau 89ms) completed a CPU burst; 12 bursts to go [Q empty]
time 64451ms: Recalculated tau from 89ms to 99ms for process B [Q empty]
time 64451ms: Process B switching out of CPU; will block on I/O until time 64903ms [Q empty]
time 64903ms: Process B (tau 99ms) completed I/O; added to ready queue [Q B]
time 64905ms: Process B (tau 99ms) started using the CPU for 41ms burst [Q empty]
time 64946ms: Process B (tau 99ms) completed a CPU burst; 11 bursts to go [Q empty]
time 64946ms: Recalculated tau from 99ms to 71ms for process B [Q empty]
time 64946ms: Process B switching out of CPU; will block on I/O until time 64978ms [Q empty]
time 64978ms: Process B (tau 71ms) completed I/O; added to ready queue [Q B]
time 64980ms: Process B (tau 71ms) started using the CPU for 36ms burst [Q empty]
time 65016ms: Process B (tau 71ms) completed a CPU burst; 10 bursts to go [Q empty]
time 65016ms: Recalculated tau from 71ms to 54ms for process B [Q empty]
time 65016ms: Process B switching out of CPU; will block on I/O until time 65798ms [Q empty]
time 65798ms: Process B (tau 54ms) completed I/O; added to ready queue [Q B]
time 65800ms: Process B (tau 54ms) started using the CPU for 228ms burst [Q empty]
time 66028ms: Process B (tau 54ms) completed a CPU burst; 9 bursts to go [Q empty]
time 66028ms: Recalculated tau from 54ms to 141ms for process B [Q empty]
time 66028ms: Process B switching out of CPU; will block on I/O until time 66200ms [Q empty]
time 66200ms: Process B (tau 141ms) completed I/O; added to ready queue [Q B]
time 66202ms: Process B (tau 141ms) started using the CPU for 137ms burst [Q empty]
time 66339ms: Process B (tau 141ms) completed a CPU burst; 8 bursts to go [Q empty]
time 66339ms: Recalculated tau from 141ms to 140ms for process B [Q empty]
time 66339ms: Process B switching out of CPU; will block on I/O until time 66661ms [Q empty]
time 66661ms: Process B (tau 140ms) completed I/O; added to ready queue [Q B]
time 66663ms: Process B (tau 140ms) started using the CPU for 167ms burst [Q empty]
time 66830ms: Process B (tau 140ms) completed a CPU burst; 7 bursts to go [Q empty]
time 66830ms: Recalculated tau from 140ms to 154ms for process B [Q empty]
time 66830ms: Process B switching out of CPU; will block on I/O until time 67782ms [Q empty]
time 67782ms: Process B (tau 154ms) completed I/O; added to ready queue [Q B]
time 67784ms: Process B (tau 154ms) started using the CPU for 25ms burst [Q empty]
time 67809ms: Process B (tau 154ms) completed a CPU burst; 6 bursts to go [Q empty]
time 67809ms: Recalculated tau from 154ms to 90ms for process B [Q empty]
time 67809ms: Process B switching out of CPU; will block on I/O until time 68991ms [Q empty]
time 68991ms: Process B (tau 90ms) completed I/O; added to ready queue [Q B]
time 68993ms: Process B (tau 90ms) started using the CPU for 109ms burst [Q empty]
time 69102ms: Process B (tau 90ms) completed a CPU burst; 5 bursts to go [Q empty]
time 69102ms: Recalculated tau from 90ms to 100ms for process B [Q empty]
time 69102ms: Process B switching out of CPU; will block on I/O until time 70194ms [Q empty]
time 70194ms: Process B (tau 100ms) completed I/O; added to ready queue [Q B]
time 70196ms: Process B (tau 100ms) started using the CPU for 197ms burst [Q empty]
time 70393ms: Process B (tau 100ms) completed a CPU burst; 4 bursts to go [Q empty]
time 70393ms: Recalculated tau from 100ms to 149ms for process B [Q empty]
time 70393ms: Process B switching out of CPU; will block on I/O until time 72665ms [Q empty]
time 72665ms: Process B (tau 149ms) completed I/O; added to ready queue [Q B]
time 72667ms: Process B (tau 149ms) started using the CPU for 292ms burst [Q empty]
time 72959ms: Process B (tau 149ms) completed a CPU burst; 3 bursts to go [Q empty]
time 72959ms: Recalculated tau from 149ms to 221ms for process B [Q empty]
time 72959ms: Process B switching out of CPU; will block on I/O until time 73451ms [Q empty]
time 73451ms: Process B (tau 221ms) completed I/O; added to ready queue [Q B]
time 73453ms: Process B (tau 221ms) started using the CPU for 12ms burst [Q empty]
time 73465ms: Process B (tau 221ms) completed a CPU burst; 2 bursts to go [Q empty]
time 73465ms: Recalculated tau from 221ms to 117ms for process B [Q empty]
time 73465ms: Process B switching out of CPU; will block on I/O until time 74077ms [Q empty]
time 74077ms: Process B (tau 117ms) completed I/O; added to ready queue [Q B]
time 74079ms: Process B (tau 117ms) started using the CPU for 299ms burst [Q empty]
time 74378ms: Process B (tau 117ms) completed a CPU burst; 1 burst to go [Q empty]
time 74378ms: Recalculated tau from 117ms to 209ms for process B [Q empty]
time 74378ms: Process B switching out of CPU; will block on I/O until time 75830ms [Q empty]
time 75830ms: Process B (tau 209ms) completed I/O; added to ready queue [Q B]
time 75832ms: Process B (tau 209ms) started using the CPU for 3ms burst [Q empty]
time 75835ms: Process B terminated [Q empty]
time 75837ms: Simulator ended for SRT [Q empty]

time 0ms: Simulator started for RR with time slice 256ms [Q empty]
time 399ms: Process B arrived; added to ready queue [Q B]
time 401ms: Process B started using the CPU for 338ms burst [Q empty]
time 482ms: Process A arrived; added to ready queue [Q A]
time 657ms: Time slice expired; process B preempted with 82ms to go [Q A]
time 661ms: Process A started using the CPU for 30ms burst [Q B]
time 691ms: Process A completed a CPU burst; 9 bursts to go [Q B]
time 691ms: Process A switching out of CPU; will block on I/O until time 3513ms [Q B]
time 695ms: Process B started using the CPU for remaining 82ms of 338ms burst [Q empty]
time 777ms: Process B completed a CPU burst; 69 bursts to go [Q empty]
time 777ms: Process B switching out of CPU; will block on I/O until time 949ms [Q empty]
time 949ms: Process B completed I/O; added to ready queue [Q B]
time 951ms: Process B started using the CPU for 95ms burst [Q empty]
time 1046ms: Process B completed a CPU burst; 68 bursts to go [Q empty]
time 1046ms: Process B switching out of CPU; will block on I/O until time 3608ms [Q empty]
time 3513ms: Process A completed I/O; added to ready queue [Q A]
time 3515ms: Process A started using the CPU for 76ms burst [Q empty]
time 3591ms: Process A completed a CPU burst; 8 bursts to go [Q empty]
time 3591ms: Process A switching out of CPU; will block on I/O until time 3913ms [Q empty]
time 3608ms: Process B completed I/O; added to ready queue [Q B]
time 3610ms: Process B started using the CPU for 324ms burst [Q empty]
time 3866ms: Time slice expired; no preemption because ready queue is empty [Q empty]
time 3913ms: Process A completed I/O; added to ready queue [Q A]
time 3934ms: Process B completed a CPU burst; 67 bursts to go [Q A]
time 3934ms: Process B switching out of CPU; will block on I/O until time 5046ms [Q A]
time 3938ms: Process A started using the CPU for 190ms burst [Q empty]
time 4128ms: Process A completed a CPU burst; 7 bursts to go [Q empty]
time 4128ms: Process A switching out of CPU; will block on I/O until time 4170ms [Q empty]
time 4170ms: Process A completed I/O; added to ready queue [Q A]
time 4172ms: Process A started using the CPU for 28ms burst [Q empty]
time 4200ms: Process A completed a CPU burst; 6 bursts to go [Q empty]
time 4200ms: Process A switching out of CPU; will block on I/O until time 5302ms [Q empty]
time 5046ms: Process B completed I/O; added to ready queue [Q B]
time 5048ms: Process B started using the CPU for 451ms burst [Q empty]
time 5302ms: Process A completed I/O; added to ready queue [Q A]
time 5304ms: Time slice expired; process B preempted with 195ms to go [Q A]
time 5308ms: Process A started using the CPU for 53ms burst [Q B]
time 5361ms: Process A completed a CPU burst; 5 bursts to go [Q B]
time 5361ms: Process A switching out of CPU; will block on I/O until time 6473ms [Q B]
time 5365ms: Process B started using the CPU for remaining 195ms of 451ms burst [Q empty]
time 5560ms: Process B completed a CPU burst; 66 bursts to go [Q empty]
time 5560ms: Process B switching out of CPU; will block on I/O until time 5712ms [Q empty]
time 5712ms: Process B completed I/O; added to ready queue [Q B]
time 5714ms: Process B started using the CPU for 57ms burst [Q empty]
time 5771ms: Process B completed a CPU burst; 65 bursts to go [Q empty]
time 5771ms: Process B switching out of CPU; will block on I/O until time 6843ms [Q empty]
time 6473ms: Process A completed I/O; added to ready queue [Q A]
time 6475ms: Process A started using the CPU for 111ms burst [Q empty]
time 6586ms: Process A completed a CPU burst; 4 bursts to go [Q empty]
time 6586ms: Process A switching out of CPU; will block on I/O until time 7298ms [Q empty]
time 6843ms: Process B completed I/O; added to ready queue [Q B]
time 6845ms: Process B started using the CPU for 244ms burst [Q empty]
time 7089ms: Process B completed a CPU burst; 64 bursts to go [Q empty]
time 7089ms: Process B switching out of CPU; will block on I/O until time 8171ms [Q empty]
time 7298ms: Process A completed I/O; added to ready queue [Q A]
time 7300ms: Process A started using the CPU for 91ms burst [Q empty]
time 7391ms: Process A completed a CPU burst; 3 bursts to go [Q empty]
time 7391ms: Process A switching out of CPU; will block on I/O until time 9183ms [Q empty]
time 8171ms: Process B completed I/O; added to ready queue [Q B]
time 8173ms: Process B started using the CPU for 84ms burst [Q empty]
time 8257ms: Process B completed a CPU burst; 63 bursts to go [Q empty]
time 8257ms: Process B switching out of CPU; will block on I/O until time 8429ms [Q empty]
time 8429ms: Process B completed I/O; added to ready queue [Q B]
time 8431ms: Process B started using the CPU for 65ms burst [Q empty]
time 8496ms: Process B completed a CPU burst; 62 bursts to go [Q empty]
time 8496ms: Process B switching out of CPU; will block on I/O until time 8988ms [Q empty]
time 8988ms: Process B completed I/O; added to ready queue [Q B]
time 8990ms: Process B started using the CPU for 55ms burst [Q empty]
time 9045ms: Process B completed a CPU burst; 61 bursts to go [Q empty]
time 9045ms: Process B switching out of CPU; will block on I/O until time 9557ms [Q empty]
time 9183ms: Process A completed I/O; added to ready queue [Q A]
time 9185ms: Process A started using the CPU for 70ms burst [Q empty]
time 9255ms: Process A completed a CPU burst; 2 bursts to go [Q empty]
time 9255ms: Process A switching out of CPU; will block on I/O until time 10337ms [Q empty]
time 9557ms: Process B completed I/O; added to ready queue [Q B]
time 9559ms: Process B started using the CPU for 71ms burst [Q empty]
time 9630ms: Process B completed a CPU burst; 60 bursts to go [Q empty]
time 9630ms: Process B switching out of CPU; will block on I/O until time 10592ms [Q empty]
time 10337ms: Process A completed I/O; added to ready queue [Q A]
time 10339ms: Process A started using the CPU for 63ms burst [Q empty]
time 10402ms: Process A completed a CPU burst; 1 burst to go [Q empty]
time 10402ms: Process A switching out of CPU; will block on I/O until time 10924ms [Q empty]
time 10592ms: Process B completed I/O; added to ready queue [Q B]
time 10594ms: Process B started using the CPU for 20ms burst [Q empty]
time 10614ms: Process B completed a CPU burst; 59 bursts to go [Q empty]
time 10614ms: Process B switching out of CPU; will block on I/O until time 11466ms [Q empty]
time 10924ms: Process A completed I/O; added to ready queue [Q A]
time 10926ms: Process A started using the CPU for 5ms burst [Q empty]
time 10931ms: Process A terminated [Q empty]
time 11466ms: Process B completed I/O; added to ready queue [Q B]
time 11468ms: Process B started using the CPU for 182ms burst [Q empty]
time 11650ms: Process B completed a CPU burst; 58 bursts to go [Q empty]
time 11650ms: Process B switching out of CPU; will block on I/O until time 13832ms [Q empty]
time 13832ms: Process B completed I/O; added to ready queue [Q B]
time 13834ms: Process B started using the CPU for 190ms burst [Q empty]
time 14024ms: Process B completed a CPU burst; 57 bursts to go [Q empty]
time 14024ms: Process B switching out of CPU; will block on I/O until time 15476ms [Q empty]
time 15476ms: Process B completed I/O; added to ready queue [Q B]
time 15478ms: Process B started using the CPU for 239ms burst [Q empty]
time 15717ms: Process B completed a CPU burst; 56 bursts to go [Q empty]
time 15717ms: Process B switching out of CPU; will block on I/O until time 19529ms [Q empty]
time 19529ms: Process B completed I/O; added to ready queue [Q B]
time 19531ms: Process B started using the CPU for 274ms burst [Q empty]
time 19787ms: Time slice expired; no preemption because ready queue is empty [Q empty]
