Process A (arrival time 482 ms) 10 CPU bursts (tau 100ms)
--> CPU burst 30 ms --> I/O burst 2820 ms
--> CPU burst 76 ms --> I/O burst 320 ms
--> CPU burst 190 ms --> I/O burst 40 ms
--> CPU burst 28 ms --> I/O burst 1100 ms
--> CPU burst 53 ms --> I/O burst 1110 ms
--> CPU burst 111 ms --> I/O burst 710 ms
--> CPU burst 91 ms --> I/O burst 1790 ms
--> CPU burst 70 ms --> I/O burst 1080 ms
--> CPU burst 63 ms --> I/O burst 520 ms
--> CPU burst 5 ms

time 0ms: Simulator started for FCFS [Q empty]
time 482ms: Process A arrived; added to ready queue [Q A]
time 484ms: Process A started using the CPU for 30ms burst [Q empty]
time 514ms: Process A completed a CPU burst; 9 bursts to go [Q empty]
time 514ms: Process A switching out of CPU; will block on I/O until time 3336ms [Q empty]
time 3336ms: Process A completed I/O; added to ready queue [Q A]
time 3338ms: Process A started using the CPU for 76ms burst [Q empty]
time 3414ms: Process A completed a CPU burst; 8 bursts to go [Q empty]
time 3414ms: Process A switching out of CPU; will block on I/O until time 3736ms [Q empty]
time 3736ms: Process A completed I/O; added to ready queue [Q A]
time 3738ms: Process A started using the CPU for 190ms burst [Q empty]
time 3928ms: Process A completed a CPU burst; 7 bursts to go [Q empty]
time 3928ms: Process A switching out of CPU; will block on I/O until time 3970ms [Q empty]
time 3970ms: Process A completed I/O; added to ready queue [Q A]
time 3972ms: Process A started using the CPU for 28ms burst [Q empty]
time 4000ms: Process A completed a CPU burst; 6 bursts to go [Q empty]
time 4000ms: Process A switching out of CPU; will block on I/O until time 5102ms [Q empty]
time 5102ms: Process A completed I/O; added to ready queue [Q A]
time 5104ms: Process A started using the CPU for 53ms burst [Q empty]
time 5157ms: Process A completed a CPU burst; 5 bursts to go [Q empty]
time 5157ms: Process A switching out of CPU; will block on I/O until time 6269ms [Q empty]
time 6269ms: Process A completed I/O; added to ready queue [Q A]
time 6271ms: Process A started using the CPU for 111ms burst [Q empty]
time 6382ms: Process A completed a CPU burst; 4 bursts to go [Q empty]
time 6382ms: Process A switching out of CPU; will block on I/O until time 7094ms [Q empty]
time 7094ms: Process A completed I/O; added to ready queue [Q A]
time 7096ms: Process A started using the CPU for 91ms burst [Q empty]
time 7187ms: Process A completed a CPU burst; 3 bursts to go [Q empty]
time 7187ms: Process A switching out of CPU; will block on I/O until time 8979ms [Q empty]
time 8979ms: Process A completed I/O; added to ready queue [Q A]
time 8981ms: Process A started using the CPU for 70ms burst [Q empty]
time 9051ms: Process A completed a CPU burst; 2 bursts to go [Q empty]
time 9051ms: Process A switching out of CPU; will block on I/O until time 10133ms [Q empty]
time 10133ms: Process A completed I/O; added to ready queue [Q A]
time 10135ms: Process A started using the CPU for 63ms burst [Q empty]
time 10198ms: Process A completed a CPU burst; 1 burst to go [Q empty]
time 10198ms: Process A switching out of CPU; will block on I/O until time 10720ms [Q empty]
time 10720ms: Process A completed I/O; added to ready queue [Q A]
time 10722ms: Process A started using the CPU for 5ms burst [Q empty]
time 10727ms: Process A terminated [Q empty]
time 10729ms: Simulator ended for FCFS [Q empty]

time 0ms: Simulator started for SJF [Q empty]
time 482ms: Process A (tau 100ms) arrived; added to ready queue [Q A]
time 484ms: Process A (tau 100ms) started using the CPU for 30ms burst [Q empty]
time 514ms: Process A (tau 100ms) completed a CPU burst; 9 bursts to go [Q empty]
time 514ms: Recalculated tau from 100ms to 65ms for process A [Q empty]
time 514ms: Process A switching out of CPU; will block on I/O until time 3336ms [Q empty]
time 3336ms: Process A (tau 65ms) completed I/O; added to ready queue [Q A]
time 3338ms: Process A (tau 65ms) started using the CPU for 76ms burst [Q empty]
time 3414ms: Process A (tau 65ms) completed a CPU burst; 8 bursts to go [Q empty]
time 3414ms: Recalculated tau from 65ms to 71ms for process A [Q empty]
time 3414ms: Process A switching out of CPU; will block on I/O until time 3736ms [Q empty]
time 3736ms: Process A (tau 71ms) completed I/O; added to ready queue [Q A]
time 3738ms: Process A (tau 71ms) started using the CPU for 190ms burst [Q empty]
time 3928ms: Process A (tau 71ms) completed a CPU burst; 7 bursts to go [Q empty]
time 3928ms: Recalculated tau from 71ms to 131ms for process A [Q empty]
time 3928ms: Process A switching out of CPU; will block on I/O until time 3970ms [Q empty]
time 3970ms: Process A (tau 131ms) completed I/O; added to ready queue [Q A]
time 3972ms: Process A (tau 131ms) started using the CPU for 28ms burst [Q empty]
time 4000ms: Process A (tau 131ms) completed a CPU burst; 6 bursts to go [Q empty]
time 4000ms: Recalculated tau from 131ms to 80ms for process A [Q empty]
time 4000ms: Process A switching out of CPU; will block on I/O until time 5102ms [Q empty]
time 5102ms: Process A (tau 80ms) completed I/O; added to ready queue [Q A]
time 5104ms: Process A (tau 80ms) started using the CPU for 53ms burst [Q empty]
time 5157ms: Process A (tau 80ms) completed a CPU burst; 5 bursts to go [Q empty]
time 5157ms: Recalculated tau from 80ms to 67ms for process A [Q empty]
time 5157ms: Process A switching out of CPU; will block on I/O until time 6269ms [Q empty]
time 6269ms: Process A (tau 67ms) completed I/O; added to ready queue [Q A]
time 6271ms: Process A (tau 67ms) started using the CPU for 111ms burst [Q empty]
time 6382ms: Process A (tau 67ms) completed a CPU burst; 4 bursts to go [Q empty]
time 6382ms: Recalculated tau from 67ms to 89ms for process A [Q empty]
time 6382ms: Process A switching out of CPU; will block on I/O until time 7094ms [Q empty]
time 7094ms: Process A (tau 89ms) completed I/O; added to ready queue [Q A]
time 7096ms: Process A (tau 89ms) started using the CPU for 91ms burst [Q empty]
time 7187ms: Process A (tau 89ms) completed a CPU burst; 3 bursts to go [Q empty]
time 7187ms: Recalculated tau from 89ms to 90ms for process A [Q empty]
time 7187ms: Process A switching out of CPU; will block on I/O until time 8979ms [Q empty]
time 8979ms: Process A (tau 90ms) completed I/O; added to ready queue [Q A]
time 8981ms: Process A (tau 90ms) started using the CPU for 70ms burst [Q empty]
time 9051ms: Process A (tau 90ms) completed a CPU burst; 2 bursts to go [Q empty]
time 9051ms: Recalculated tau from 90ms to 80ms for process A [Q empty]
time 9051ms: Process A switching out of CPU; will block on I/O until time 10133ms [Q empty]
time 10133ms: Process A (tau 80ms) completed I/O; added to ready queue [Q A]
time 10135ms: Process A (tau 80ms) started using the CPU for 63ms burst [Q empty]
time 10198ms: Process A (tau 80ms) completed a CPU burst; 1 burst to go [Q empty]
time 10198ms: Recalculated tau from 80ms to 72ms for process A [Q empty]
time 10198ms: Process A switching out of CPU; will block on I/O until time 10720ms [Q empty]
time 10720ms: Process A (tau 72ms) completed I/O; added to ready queue [Q A]
time 10722ms: Process A (tau 72ms) started using the CPU for 5ms burst [Q empty]
time 10727ms: Process A terminated [Q empty]
time 10729ms: Simulator ended for SJF [Q empty]

time 0ms: Simulator started for SRT [Q empty]
time 482ms: Process A (tau 100ms) arrived; added to ready queue [Q A]
time 484ms: Process A (tau 100ms) started using the CPU for 30ms burst [Q empty]
time 514ms: Process A (tau 100ms) completed a CPU burst; 9 bursts to go [Q empty]
time 514ms: Recalculated tau from 100ms to 65ms for process A [Q empty]
time 514ms: Process A switching out of CPU; will block on I/O until time 3336ms [Q empty]
time 3336ms: Process A (tau 65ms) completed I/O; added to ready queue [Q A]
time 3338ms: Process A (tau 65ms) started using the CPU for 76ms burst [Q empty]
time 3414ms: Process A (tau 65ms) completed a CPU burst; 8 bursts to go [Q empty]
time 3414ms: Recalculated tau from 65ms to 71ms for process A [Q empty]
time 3414ms: Process A switching out of CPU; will block on I/O until time 3736ms [Q empty]
time 3736ms: Process A (tau 71ms) completed I/O; added to ready queue [Q A]
time 3738ms: Process A (tau 71ms) started using the CPU for 190ms burst [Q empty]
time 3928ms: Process A (tau 71ms) completed a CPU burst; 7 bursts to go [Q empty]
time 3928ms: Recalculated tau from 71ms to 131ms for process A [Q empty]
time 3928ms: Process A switching out of CPU; will block on I/O until time 3970ms [Q empty]
time 3970ms: Process A (tau 131ms) completed I/O; added to ready queue [Q A]
time 3972ms: Process A (tau 131ms) started using the CPU for 28ms burst [Q empty]
time 4000ms: Process A (tau 131ms) completed a CPU burst; 6 bursts to go [Q empty]
time 4000ms: Recalculated tau from 131ms to 80ms for process A [Q empty]
time 4000ms: Process A switching out of CPU; will block on I/O until time 5102ms [Q empty]
time 5102ms: Process A (tau 80ms) completed I/O; added to ready queue [Q A]
time 5104ms: Process A (tau 80ms) started using the CPU for 53ms burst [Q empty]
time 5157ms: Process A (tau 80ms) completed a CPU burst; 5 bursts to go [Q empty]
time 5157ms: Recalculated tau from 80ms to 67ms for process A [Q empty]
time 5157ms: Process A switching out of CPU; will block on I/O until time 6269ms [Q empty]
time 6269ms: Process A (tau 67ms) completed I/O; added to ready queue [Q A]
time 6271ms: Process A (tau 67ms) started using the CPU for 111ms burst [Q empty]
time 6382ms: Process A (tau 67ms) completed a CPU burst; 4 bursts to go [Q empty]
time 6382ms: Recalculated tau from 67ms to 89ms for process A [Q empty]
time 6382ms: Process A switching out of CPU; will block on I/O until time 7094ms [Q empty]
time 7094ms: Process A (tau 89ms) completed I/O; added to ready queue [Q A]
time 7096ms: Process A (tau 89ms) started using the CPU for 91ms burst [Q empty]
time 7187ms: Process A (tau 89ms) completed a CPU burst; 3 bursts to go [Q empty]
time 7187ms: Recalculated tau from 89ms to 90ms for process A [Q empty]
time 7187ms: Process A switching out of CPU; will block on I/O until time 8979ms [Q empty]
time 8979ms: Process A (tau 90ms) completed I/O; added to ready queue [Q A]
time 8981ms: Process A (tau 90ms) started using the CPU for 70ms burst [Q empty]
time 9051ms: Process A (tau 90ms) completed a CPU burst; 2 bursts to go [Q empty]
time 9051ms: Recalculated tau from 90ms to 80ms for process A [Q empty]
time 9051ms: Process A switching out of CPU; will block on I/O until time 10133ms [Q empty]
time 10133ms: Process A (tau 80ms) completed I/O; added to ready queue [Q A]
time 10135ms: Process A (tau 80ms) started using the CPU for 63ms burst [Q empty]
time 10198ms: Process A (tau 80ms) completed a CPU burst; 1 burst to go [Q empty]
time 10198ms: Recalculated tau from 80ms to 72ms for process A [Q empty]
time 10198ms: Process A switching out of CPU; will block on I/O until time 10720ms [Q empty]
time 10720ms: Process A (tau 72ms) completed I/O; added to ready queue [Q A]
time 10722ms: Process A (tau 72ms) started using the CPU for 5ms burst [Q empty]
time 10727ms: Process A terminated [Q empty]
time 10729ms: Simulator ended for SRT [Q empty]

time 0ms: Simulator started for RR with time slice 256ms [Q empty]
time 482ms: Process A arrived; added to ready queue [Q A]
time 484ms: Process A started using the CPU for 30ms burst [Q empty]
time 514ms: Process A completed a CPU burst; 9 bursts to go [Q empty]
time 514ms: Process A switching out of CPU; will block on I/O until time 3336ms [Q empty]
time 3336ms: Process A completed I/O; added to ready queue [Q A]
time 3338ms: Process A started using the CPU for 76ms burst [Q empty]
time 3414ms: Process A completed a CPU burst; 8 bursts to go [Q empty]
time 3414ms: Process A switching out of CPU; will block on I/O until time 3736ms [Q empty]
time 3736ms: Process A completed I/O; added to ready queue [Q A]
time 3738ms: Process A started using the CPU for 190ms burst [Q empty]
time 3928ms: Process A completed a CPU burst; 7 bursts to go [Q empty]
time 3928ms: Process A switching out of CPU; will block on I/O until time 3970ms [Q empty]
time 3970ms: Process A completed I/O; added to ready queue [Q A]
time 3972ms: Process A started using the CPU for 28ms burst [Q empty]
time 4000ms: Process A completed a CPU burst; 6 bursts to go [Q empty]
time 4000ms: Process A switching out of CPU; will block on I/O until time 5102ms [Q empty]
time 5102ms: Process A completed I/O; added to ready queue [Q A]
time 5104ms: Process A started using the CPU for 53ms burst [Q empty]
time 5157ms: Process A completed a CPU burst; 5 bursts to go [Q empty]
time 5157ms: Process A switching out of CPU; will block on I/O until time 6269ms [Q empty]
time 6269ms: Process A completed I/O; added to ready queue [Q A]
time 6271ms: Process A started using the CPU for 111ms burst [Q empty]
time 6382ms: Process A completed a CPU burst; 4 bursts to go [Q empty]
time 6382ms: Process A switching out of CPU; will block on I/O until time 7094ms [Q empty]
time 7094ms: Process A completed I/O; added to ready queue [Q A]
time 7096ms: Process A started using the CPU for 91ms burst [Q empty]
time 7187ms: Process A completed a CPU burst; 3 bursts to go [Q empty]
time 7187ms: Process A switching out of CPU; will block on I/O until time 8979ms [Q empty]
time 8979ms: Process A completed I/O; added to ready queue [Q A]
time 8981ms: Process A started using the CPU for 70ms burst [Q empty]
time 9051ms: Process A completed a CPU burst; 2 bursts to go [Q empty]
time 9051ms: Process A switching out of CPU; will block on I/O until time 10133ms [Q empty]
time 10133ms: Process A completed I/O; added to ready queue [Q A]
time 10135ms: Process A started using the CPU for 63ms burst [Q empty]
time 10198ms: Process A completed a CPU burst; 1 burst to go [Q empty]
time 10198ms: Process A switching out of CPU; will block on I/O until time 10720ms [Q empty]
time 10720ms: Process A completed I/O; added to ready queue [Q A]
time 10722ms: Process A started using the CPU for 5ms burst [Q empty]
time 10727ms: Process A terminated [Q empty]
time 10729ms: Simulator ended for RR [Q empty]
